package mjaroslav.mcmods.peatized.common.world;

import java.util.ArrayList;
import java.util.Random;

import mjaroslav.mcmods.peatized.common.config.PeatizedConfig;
import mjaroslav.mcmods.peatized.common.init.PeatizedBlocks;
import mjaroslav.mcmods.peatized.common.init.PeatizedWorldGen;
import net.minecraft.block.Block;
import net.minecraft.block.material.Material;
import net.minecraft.entity.passive.EntityVillager;
import net.minecraft.init.Blocks;
import net.minecraft.tileentity.TileEntityChest;
import net.minecraft.util.WeightedRandomChestContent;
import net.minecraft.world.World;
import net.minecraftforge.common.BiomeDictionary;

public class PeathouseGenerator extends BaseWorldGenerator {
	public Block[] validSpawnBlocks = new Block[] { Blocks.grass, Blocks.stone, PeatizedBlocks.bogDirtGenerated };
	private int rotation;

	@Override
	public boolean canGenerate(World world, Random rand, int x, int y, int z) {
		if (!(PeatizedConfig.peathousePercentChance >= 100 || (PeatizedConfig.peathousePercentChance != 0
				&& rand.nextInt(200) < PeatizedConfig.peathousePercentChance)))
			return false;
		if (!BiomeDictionary.isBiomeOfType(world.getBiomeGenForCoords(x, z), BiomeDictionary.Type.SWAMP))
			return false;
		return true;
	}

	@Override
	public int[] getCoords(World world, Random rand, int chunkX, int chunkZ) {
		int x = chunkX * 16 + rand.nextInt(16) + 8;
		int z = chunkZ * 16 + rand.nextInt(16) + 8;
		int y = 63;
		while (world.getBlock(x, y, z) != Blocks.air)
			y++;
		this.rotation = rand.nextInt(4);
		return new int[] { x, y, z };
	}

	public boolean canGenerateLocal(World world, int x, int y, int z, int x1, int z1) {
		ArrayList<Integer> hs = new ArrayList<Integer>();
		int id = 0;
		for (int xx = x; xx < x1 + 1; xx++)
			for (int zz = z; zz < z1 + 1; zz++) {
				if (world.getBlock(x, y-1, z).getMaterial() != Material.water)
					return false;
			}
		return true;
	}

	@Override
	public boolean generate(World world, Random rand, int x, int y, int z) {
		if (this.rotation == 0) {
			return generateR0(world, rand, x, y, z);
		}
		if (this.rotation == 1) {
			return generateR1(world, rand, x, y, z);
		}
		if (this.rotation == 2) {
			return generateR2(world, rand, x, y, z);
		}
		if (this.rotation == 3) {
			return generateR3(world, rand, x, y, z);
		}
		return false;
	}

	public boolean generateR0(World world, Random rand, int x, int y, int z) {
		if (!canGenerateLocal(world, x, y, z, x + 9, z + 6)) {
			return false;
		}
		world.setBlock(x + 0, y + -1, z + 0, Blocks.cobblestone, 0, 3);
		world.setBlock(x + 1, y + -1, z + 0, Blocks.cobblestone, 0, 3);
		world.setBlock(x + 2, y + -1, z + 0, Blocks.cobblestone, 0, 3);
		world.setBlock(x + 3, y + -1, z + 0, Blocks.cobblestone, 0, 3);
		world.setBlock(x + 4, y + -1, z + 0, Blocks.cobblestone, 0, 3);
		world.setBlock(x + 5, y + -1, z + 0, Blocks.cobblestone, 0, 3);
		world.setBlock(x + 6, y + -1, z + 0, Blocks.cobblestone, 0, 3);
		world.setBlock(x + 7, y + -1, z + 0, Blocks.cobblestone, 0, 3);
		world.setBlock(x + 8, y + -1, z + 0, Blocks.cobblestone, 0, 3);
		world.setBlock(x + 9, y + -1, z + 0, Blocks.cobblestone, 0, 3);
		world.setBlock(x + 0, y + -1, z + 1, Blocks.cobblestone, 0, 3);
		world.setBlock(x + 1, y + -1, z + 1, Blocks.cobblestone, 0, 3);
		world.setBlock(x + 2, y + -1, z + 1, Blocks.cobblestone, 0, 3);
		world.setBlock(x + 3, y + -1, z + 1, Blocks.cobblestone, 0, 3);
		world.setBlock(x + 4, y + -1, z + 1, Blocks.cobblestone, 0, 3);
		world.setBlock(x + 5, y + -1, z + 1, Blocks.cobblestone, 0, 3);
		world.setBlock(x + 6, y + -1, z + 1, Blocks.cobblestone, 0, 3);
		world.setBlock(x + 7, y + -1, z + 1, Blocks.cobblestone, 0, 3);
		world.setBlock(x + 8, y + -1, z + 1, Blocks.cobblestone, 0, 3);
		world.setBlock(x + 9, y + -1, z + 1, Blocks.cobblestone, 0, 3);
		world.setBlock(x + 0, y + -1, z + 2, Blocks.cobblestone, 0, 3);
		world.setBlock(x + 1, y + -1, z + 2, Blocks.cobblestone, 0, 3);
		world.setBlock(x + 2, y + -1, z + 2, Blocks.cobblestone, 0, 3);
		world.setBlock(x + 3, y + -1, z + 2, Blocks.cobblestone, 0, 3);
		world.setBlock(x + 4, y + -1, z + 2, Blocks.cobblestone, 0, 3);
		world.setBlock(x + 5, y + -1, z + 2, Blocks.cobblestone, 0, 3);
		world.setBlock(x + 6, y + -1, z + 2, Blocks.cobblestone, 0, 3);
		world.setBlock(x + 7, y + -1, z + 2, Blocks.cobblestone, 0, 3);
		world.setBlock(x + 8, y + -1, z + 2, Blocks.cobblestone, 0, 3);
		world.setBlock(x + 9, y + -1, z + 2, Blocks.cobblestone, 0, 3);
		world.setBlock(x + 0, y + -1, z + 3, Blocks.cobblestone, 0, 3);
		world.setBlock(x + 1, y + -1, z + 3, Blocks.cobblestone, 0, 3);
		world.setBlock(x + 2, y + -1, z + 3, Blocks.cobblestone, 0, 3);
		world.setBlock(x + 3, y + -1, z + 3, Blocks.cobblestone, 0, 3);
		world.setBlock(x + 4, y + -1, z + 3, Blocks.cobblestone, 0, 3);
		world.setBlock(x + 5, y + -1, z + 3, Blocks.cobblestone, 0, 3);
		world.setBlock(x + 6, y + -1, z + 3, Blocks.cobblestone, 0, 3);
		world.setBlock(x + 7, y + -1, z + 3, Blocks.cobblestone, 0, 3);
		world.setBlock(x + 8, y + -1, z + 3, Blocks.cobblestone, 0, 3);
		world.setBlock(x + 9, y + -1, z + 3, Blocks.cobblestone, 0, 3);
		world.setBlock(x + 0, y + -1, z + 4, Blocks.cobblestone, 0, 3);
		world.setBlock(x + 1, y + -1, z + 4, Blocks.cobblestone, 0, 3);
		world.setBlock(x + 2, y + -1, z + 4, Blocks.cobblestone, 0, 3);
		world.setBlock(x + 3, y + -1, z + 4, Blocks.cobblestone, 0, 3);
		world.setBlock(x + 4, y + -1, z + 4, Blocks.cobblestone, 0, 3);
		world.setBlock(x + 5, y + -1, z + 4, Blocks.cobblestone, 0, 3);
		world.setBlock(x + 6, y + -1, z + 4, Blocks.cobblestone, 0, 3);
		world.setBlock(x + 7, y + -1, z + 4, Blocks.cobblestone, 0, 3);
		world.setBlock(x + 8, y + -1, z + 4, Blocks.cobblestone, 0, 3);
		world.setBlock(x + 9, y + -1, z + 4, Blocks.cobblestone, 0, 3);
		world.setBlock(x + 0, y + -1, z + 5, Blocks.cobblestone, 0, 3);
		world.setBlock(x + 1, y + -1, z + 5, Blocks.cobblestone, 0, 3);
		world.setBlock(x + 2, y + -1, z + 5, Blocks.cobblestone, 0, 3);
		world.setBlock(x + 3, y + -1, z + 5, Blocks.cobblestone, 0, 3);
		world.setBlock(x + 4, y + -1, z + 5, Blocks.cobblestone, 0, 3);
		world.setBlock(x + 5, y + -1, z + 5, Blocks.cobblestone, 0, 3);
		world.setBlock(x + 6, y + -1, z + 5, Blocks.cobblestone, 0, 3);
		world.setBlock(x + 7, y + -1, z + 5, Blocks.cobblestone, 0, 3);
		world.setBlock(x + 8, y + -1, z + 5, Blocks.cobblestone, 0, 3);
		world.setBlock(x + 9, y + -1, z + 5, Blocks.cobblestone, 0, 3);
		world.setBlock(x + 0, y + -1, z + 6, Blocks.cobblestone, 0, 3);
		world.setBlock(x + 1, y + -1, z + 6, Blocks.cobblestone, 0, 3);
		world.setBlock(x + 2, y + -1, z + 6, Blocks.cobblestone, 0, 3);
		world.setBlock(x + 3, y + -1, z + 6, Blocks.cobblestone, 0, 3);
		world.setBlock(x + 4, y + -1, z + 6, Blocks.cobblestone, 0, 3);
		world.setBlock(x + 5, y + -1, z + 6, Blocks.cobblestone, 0, 3);
		world.setBlock(x + 6, y + -1, z + 6, Blocks.cobblestone, 0, 3);
		world.setBlock(x + 7, y + -1, z + 6, Blocks.cobblestone, 0, 3);
		world.setBlock(x + 8, y + -1, z + 6, Blocks.cobblestone, 0, 3);
		world.setBlock(x + 9, y + -1, z + 6, Blocks.cobblestone, 0, 3);
		world.setBlock(x + 0, y + 0, z + 0, Blocks.air, 0, 3);
		world.setBlock(x + 1, y + 0, z + 0, Blocks.air, 0, 3);
		world.setBlock(x + 2, y + 0, z + 0, Blocks.air, 0, 3);
		world.setBlock(x + 3, y + 0, z + 0, Blocks.air, 0, 3);
		world.setBlock(x + 4, y + 0, z + 0, Blocks.air, 0, 3);
		world.setBlock(x + 5, y + 0, z + 0, Blocks.air, 0, 3);
		world.setBlock(x + 6, y + 0, z + 0, Blocks.air, 0, 3);
		world.setBlock(x + 7, y + 0, z + 0, Blocks.air, 0, 3);
		world.setBlock(x + 8, y + 0, z + 0, Blocks.air, 0, 3);
		world.setBlock(x + 9, y + 0, z + 0, Blocks.air, 0, 3);
		world.setBlock(x + 0, y + 0, z + 1, Blocks.air, 0, 3);
		world.setBlock(x + 1, y + 0, z + 1, PeatizedBlocks.peat, 0, 3);
		world.setBlock(x + 2, y + 0, z + 1, PeatizedBlocks.peat, 0, 3);
		world.setBlock(x + 3, y + 0, z + 1, PeatizedBlocks.peat, 0, 3);
		world.setBlock(x + 4, y + 0, z + 1, PeatizedBlocks.peat, 0, 3);
		world.setBlock(x + 5, y + 0, z + 1, PeatizedBlocks.peat, 0, 3);
		world.setBlock(x + 6, y + 0, z + 1, PeatizedBlocks.peat, 0, 3);
		world.setBlock(x + 7, y + 0, z + 1, PeatizedBlocks.peat, 0, 3);
		world.setBlock(x + 8, y + 0, z + 1, Blocks.log, 0, 3);
		world.setBlock(x + 9, y + 0, z + 1, Blocks.air, 0, 3);
		world.setBlock(x + 0, y + 0, z + 2, Blocks.brick_block, 0, 3);
		world.setBlock(x + 1, y + 0, z + 2, Blocks.brick_block, 0, 3);
		world.setBlock(x + 2, y + 0, z + 2, Blocks.brick_block, 0, 3);
		world.setBlock(x + 3, y + 0, z + 2, PeatizedBlocks.peat, 0, 3);
		world.setBlock(x + 4, y + 0, z + 2, PeatizedBlocks.peat, 0, 3);
		world.setBlock(x + 5, y + 0, z + 2, PeatizedBlocks.peat, 0, 3);
		world.setBlock(x + 6, y + 0, z + 2, PeatizedBlocks.peat, 0, 3);
		world.setBlock(x + 7, y + 0, z + 2, PeatizedBlocks.peat, 0, 3);
		world.setBlock(x + 8, y + 0, z + 2, PeatizedBlocks.peat, 0, 3);
		world.setBlock(x + 9, y + 0, z + 2, Blocks.air, 0, 3);
		world.setBlock(x + 0, y + 0, z + 3, Blocks.brick_block, 0, 3);
		world.setBlock(x + 1, y + 0, z + 3, Blocks.brick_block, 0, 3);
		world.setBlock(x + 2, y + 0, z + 3, Blocks.brick_block, 0, 3);
		world.setBlock(x + 3, y + 0, z + 3, PeatizedBlocks.peat, 0, 3);
		world.setBlock(x + 4, y + 0, z + 3, PeatizedBlocks.peat, 0, 3);
		world.setBlock(x + 5, y + 0, z + 3, PeatizedBlocks.peat, 0, 3);
		world.setBlock(x + 6, y + 0, z + 3, PeatizedBlocks.peat, 0, 3);
		world.setBlock(x + 7, y + 0, z + 3, PeatizedBlocks.peat, 0, 3);
		world.setBlock(x + 8, y + 0, z + 3, PeatizedBlocks.peat, 0, 3);
		world.setBlock(x + 9, y + 0, z + 3, Blocks.air, 0, 3);
		world.setBlock(x + 0, y + 0, z + 4, Blocks.brick_block, 0, 3);
		world.setBlock(x + 1, y + 0, z + 4, Blocks.brick_block, 0, 3);
		world.setBlock(x + 2, y + 0, z + 4, Blocks.brick_block, 0, 3);
		world.setBlock(x + 3, y + 0, z + 4, PeatizedBlocks.peat, 0, 3);
		world.setBlock(x + 4, y + 0, z + 4, PeatizedBlocks.peat, 0, 3);
		world.setBlock(x + 5, y + 0, z + 4, PeatizedBlocks.peat, 0, 3);
		world.setBlock(x + 6, y + 0, z + 4, PeatizedBlocks.peat, 0, 3);
		world.setBlock(x + 7, y + 0, z + 4, PeatizedBlocks.peat, 0, 3);
		world.setBlock(x + 8, y + 0, z + 4, PeatizedBlocks.peat, 0, 3);
		world.setBlock(x + 9, y + 0, z + 4, Blocks.air, 0, 3);
		world.setBlock(x + 0, y + 0, z + 5, Blocks.air, 0, 3);
		world.setBlock(x + 1, y + 0, z + 5, PeatizedBlocks.peat, 0, 3);
		world.setBlock(x + 2, y + 0, z + 5, PeatizedBlocks.peat, 0, 3);
		world.setBlock(x + 3, y + 0, z + 5, PeatizedBlocks.peat, 0, 3);
		world.setBlock(x + 4, y + 0, z + 5, PeatizedBlocks.peat, 0, 3);
		world.setBlock(x + 5, y + 0, z + 5, PeatizedBlocks.peat, 0, 3);
		world.setBlock(x + 6, y + 0, z + 5, PeatizedBlocks.peat, 0, 3);
		world.setBlock(x + 7, y + 0, z + 5, PeatizedBlocks.peat, 0, 3);
		world.setBlock(x + 8, y + 0, z + 5, Blocks.log, 0, 3);
		world.setBlock(x + 9, y + 0, z + 5, Blocks.air, 0, 3);
		world.setBlock(x + 0, y + 0, z + 6, Blocks.air, 0, 3);
		world.setBlock(x + 1, y + 0, z + 6, Blocks.air, 0, 3);
		world.setBlock(x + 2, y + 0, z + 6, Blocks.air, 0, 3);
		world.setBlock(x + 3, y + 0, z + 6, Blocks.air, 0, 3);
		world.setBlock(x + 4, y + 0, z + 6, Blocks.air, 0, 3);
		world.setBlock(x + 5, y + 0, z + 6, Blocks.air, 0, 3);
		world.setBlock(x + 6, y + 0, z + 6, Blocks.air, 0, 3);
		world.setBlock(x + 7, y + 0, z + 6, Blocks.air, 0, 3);
		world.setBlock(x + 8, y + 0, z + 6, Blocks.air, 0, 3);
		world.setBlock(x + 9, y + 0, z + 6, Blocks.air, 0, 3);
		world.setBlock(x + 0, y + 1, z + 0, Blocks.air, 0, 3);
		world.setBlock(x + 1, y + 1, z + 0, Blocks.air, 0, 3);
		world.setBlock(x + 2, y + 1, z + 0, Blocks.air, 0, 3);
		world.setBlock(x + 3, y + 1, z + 0, Blocks.air, 0, 3);
		world.setBlock(x + 4, y + 1, z + 0, Blocks.air, 0, 3);
		world.setBlock(x + 5, y + 1, z + 0, Blocks.air, 0, 3);
		world.setBlock(x + 6, y + 1, z + 0, Blocks.air, 0, 3);
		world.setBlock(x + 7, y + 1, z + 0, Blocks.air, 0, 3);
		world.setBlock(x + 8, y + 1, z + 0, Blocks.air, 0, 3);
		world.setBlock(x + 9, y + 1, z + 0, Blocks.air, 0, 3);
		world.setBlock(x + 0, y + 1, z + 1, Blocks.air, 0, 3);
		world.setBlock(x + 1, y + 1, z + 1, Blocks.log, 0, 3);
		world.setBlock(x + 2, y + 1, z + 1, Blocks.planks, 0, 3);
		world.setBlock(x + 3, y + 1, z + 1, Blocks.planks, 0, 3);
		world.setBlock(x + 4, y + 1, z + 1, Blocks.planks, 0, 3);
		world.setBlock(x + 5, y + 1, z + 1, Blocks.planks, 0, 3);
		world.setBlock(x + 6, y + 1, z + 1, Blocks.planks, 0, 3);
		world.setBlock(x + 7, y + 1, z + 1, Blocks.planks, 0, 3);
		world.setBlock(x + 8, y + 1, z + 1, Blocks.log, 0, 3);
		world.setBlock(x + 9, y + 1, z + 1, Blocks.air, 0, 3);
		world.setBlock(x + 0, y + 1, z + 2, Blocks.brick_stairs, 0, 3);
		world.setBlock(x + 1, y + 1, z + 2, Blocks.brick_block, 0, 3);
		world.setBlock(x + 2, y + 1, z + 2, Blocks.brick_stairs, 1, 3);
		world.setBlock(x + 3, y + 1, z + 2, Blocks.air, 0, 3);
		world.setBlock(x + 6, y + 1, z + 2, Blocks.air, 0, 3);
		world.setBlock(x + 8, y + 1, z + 2, Blocks.planks, 0, 3);
		world.setBlock(x + 9, y + 1, z + 2, Blocks.air, 0, 3);
		world.setBlock(x + 0, y + 1, z + 3, Blocks.brick_block, 0, 3);
		world.setBlock(x + 2, y + 1, z + 3, Blocks.air, 0, 3);
		world.setBlock(x + 3, y + 1, z + 3, Blocks.air, 0, 3);
		world.setBlock(x + 4, y + 1, z + 3, Blocks.air, 0, 3);
		world.setBlock(x + 5, y + 1, z + 3, Blocks.air, 0, 3);
		world.setBlock(x + 6, y + 1, z + 3, Blocks.air, 0, 3);
		world.setBlock(x + 8, y + 1, z + 3, Blocks.planks, 0, 3);
		world.setBlock(x + 9, y + 1, z + 3, Blocks.air, 0, 3);
		world.setBlock(x + 0, y + 1, z + 4, Blocks.brick_stairs, 0, 3);
		world.setBlock(x + 1, y + 1, z + 4, Blocks.brick_block, 0, 3);
		world.setBlock(x + 2, y + 1, z + 4, Blocks.brick_stairs, 1, 3);
		world.setBlock(x + 3, y + 1, z + 4, Blocks.air, 0, 3);
		world.setBlock(x + 4, y + 1, z + 4, Blocks.air, 0, 3);
		world.setBlock(x + 5, y + 1, z + 4, Blocks.air, 0, 3);
		world.setBlock(x + 6, y + 1, z + 4, Blocks.air, 0, 3);
		world.setBlock(x + 7, y + 1, z + 4, Blocks.air, 0, 3);
		world.setBlock(x + 8, y + 1, z + 4, Blocks.planks, 0, 3);
		world.setBlock(x + 9, y + 1, z + 4, Blocks.air, 0, 3);
		world.setBlock(x + 0, y + 1, z + 5, Blocks.air, 0, 3);
		world.setBlock(x + 1, y + 1, z + 5, Blocks.log, 0, 3);
		world.setBlock(x + 2, y + 1, z + 5, Blocks.planks, 0, 3);
		world.setBlock(x + 3, y + 1, z + 5, Blocks.planks, 0, 3);
		world.setBlock(x + 4, y + 1, z + 5, Blocks.planks, 0, 3);
		world.setBlock(x + 5, y + 1, z + 5, Blocks.planks, 0, 3);
		world.setBlock(x + 7, y + 1, z + 5, Blocks.planks, 0, 3);
		world.setBlock(x + 8, y + 1, z + 5, Blocks.log, 0, 3);
		world.setBlock(x + 9, y + 1, z + 5, Blocks.air, 0, 3);
		world.setBlock(x + 0, y + 1, z + 6, Blocks.air, 0, 3);
		world.setBlock(x + 1, y + 1, z + 6, Blocks.air, 0, 3);
		world.setBlock(x + 2, y + 1, z + 6, Blocks.air, 0, 3);
		world.setBlock(x + 3, y + 1, z + 6, Blocks.air, 0, 3);
		world.setBlock(x + 4, y + 1, z + 6, Blocks.air, 0, 3);
		world.setBlock(x + 5, y + 1, z + 6, Blocks.air, 0, 3);
		world.setBlock(x + 6, y + 1, z + 6, Blocks.air, 0, 3);
		world.setBlock(x + 7, y + 1, z + 6, Blocks.air, 0, 3);
		world.setBlock(x + 8, y + 1, z + 6, Blocks.air, 0, 3);
		world.setBlock(x + 9, y + 1, z + 6, Blocks.air, 0, 3);
		world.setBlock(x + 0, y + 2, z + 0, Blocks.air, 0, 3);
		world.setBlock(x + 1, y + 2, z + 0, Blocks.air, 0, 3);
		world.setBlock(x + 2, y + 2, z + 0, Blocks.air, 0, 3);
		world.setBlock(x + 3, y + 2, z + 0, Blocks.air, 0, 3);
		world.setBlock(x + 4, y + 2, z + 0, Blocks.air, 0, 3);
		world.setBlock(x + 5, y + 2, z + 0, Blocks.air, 0, 3);
		world.setBlock(x + 6, y + 2, z + 0, Blocks.air, 0, 3);
		world.setBlock(x + 7, y + 2, z + 0, Blocks.air, 0, 3);
		world.setBlock(x + 8, y + 2, z + 0, Blocks.air, 0, 3);
		world.setBlock(x + 9, y + 2, z + 0, Blocks.air, 0, 3);
		world.setBlock(x + 0, y + 2, z + 1, Blocks.air, 0, 3);
		world.setBlock(x + 1, y + 2, z + 1, Blocks.log, 0, 3);
		world.setBlock(x + 2, y + 2, z + 1, PeatizedBlocks.peat, 1, 3);
		world.setBlock(x + 3, y + 2, z + 1, Blocks.stained_glass_pane, 7, 3);
		world.setBlock(x + 4, y + 2, z + 1, PeatizedBlocks.peat, 1, 3);
		world.setBlock(x + 5, y + 2, z + 1, PeatizedBlocks.peat, 1, 3);
		world.setBlock(x + 6, y + 2, z + 1, Blocks.stained_glass_pane, 7, 3);
		world.setBlock(x + 7, y + 2, z + 1, PeatizedBlocks.peat, 1, 3);
		world.setBlock(x + 8, y + 2, z + 1, Blocks.log, 0, 3);
		world.setBlock(x + 9, y + 2, z + 1, Blocks.air, 0, 3);
		world.setBlock(x + 0, y + 2, z + 2, Blocks.air, 0, 3);
		world.setBlock(x + 1, y + 2, z + 2, PeatizedBlocks.peat, 0, 3);
		world.setBlock(x + 2, y + 2, z + 2, Blocks.air, 0, 3);
		world.setBlock(x + 3, y + 2, z + 2, Blocks.air, 0, 3);
		world.setBlock(x + 4, y + 2, z + 2, Blocks.air, 0, 3);
		world.setBlock(x + 5, y + 2, z + 2, Blocks.air, 0, 3);
		world.setBlock(x + 6, y + 2, z + 2, Blocks.air, 0, 3);
		world.setBlock(x + 7, y + 2, z + 2, Blocks.air, 0, 3);
		world.setBlock(x + 8, y + 2, z + 2, PeatizedBlocks.peat, 1, 3);
		world.setBlock(x + 9, y + 2, z + 2, Blocks.air, 0, 3);
		world.setBlock(x + 0, y + 2, z + 3, Blocks.brick_stairs, 0, 3);
		world.setBlock(x + 1, y + 2, z + 3, Blocks.brick_block, 0, 3);
		world.setBlock(x + 2, y + 2, z + 3, Blocks.air, 0, 3);
		world.setBlock(x + 3, y + 2, z + 3, Blocks.air, 0, 3);
		world.setBlock(x + 4, y + 2, z + 3, Blocks.air, 0, 3);
		world.setBlock(x + 5, y + 2, z + 3, Blocks.air, 0, 3);
		world.setBlock(x + 6, y + 2, z + 3, Blocks.air, 0, 3);
		world.setBlock(x + 7, y + 2, z + 3, Blocks.air, 0, 3);
		world.setBlock(x + 8, y + 2, z + 3, Blocks.stained_glass_pane, 7, 3);
		world.setBlock(x + 9, y + 2, z + 3, Blocks.air, 0, 3);
		world.setBlock(x + 0, y + 2, z + 4, Blocks.air, 0, 3);
		world.setBlock(x + 1, y + 2, z + 4, PeatizedBlocks.peat, 0, 3);
		world.setBlock(x + 2, y + 2, z + 4, Blocks.air, 0, 3);
		world.setBlock(x + 3, y + 2, z + 4, Blocks.air, 0, 3);
		world.setBlock(x + 4, y + 2, z + 4, Blocks.air, 0, 3);
		world.setBlock(x + 6, y + 2, z + 4, Blocks.air, 0, 3);
		world.setBlock(x + 7, y + 2, z + 4, Blocks.air, 0, 3);
		world.setBlock(x + 8, y + 2, z + 4, PeatizedBlocks.peat, 1, 3);
		world.setBlock(x + 9, y + 2, z + 4, Blocks.air, 0, 3);
		world.setBlock(x + 0, y + 2, z + 5, Blocks.air, 0, 3);
		world.setBlock(x + 1, y + 2, z + 5, Blocks.log, 0, 3);
		world.setBlock(x + 2, y + 2, z + 5, PeatizedBlocks.peat, 1, 3);
		world.setBlock(x + 3, y + 2, z + 5, Blocks.stained_glass_pane, 7, 3);
		world.setBlock(x + 4, y + 2, z + 5, Blocks.stained_glass_pane, 7, 3);
		world.setBlock(x + 5, y + 2, z + 5, PeatizedBlocks.peat, 1, 3);
		world.setBlock(x + 7, y + 2, z + 5, PeatizedBlocks.peat, 1, 3);
		world.setBlock(x + 8, y + 2, z + 5, Blocks.log, 0, 3);
		world.setBlock(x + 9, y + 2, z + 5, Blocks.air, 0, 3);
		world.setBlock(x + 0, y + 2, z + 6, Blocks.air, 0, 3);
		world.setBlock(x + 1, y + 2, z + 6, Blocks.air, 0, 3);
		world.setBlock(x + 2, y + 2, z + 6, Blocks.air, 0, 3);
		world.setBlock(x + 3, y + 2, z + 6, Blocks.air, 0, 3);
		world.setBlock(x + 4, y + 2, z + 6, Blocks.air, 0, 3);
		world.setBlock(x + 6, y + 2, z + 6, Blocks.air, 0, 3);
		world.setBlock(x + 7, y + 2, z + 6, Blocks.air, 0, 3);
		world.setBlock(x + 8, y + 2, z + 6, Blocks.air, 0, 3);
		world.setBlock(x + 9, y + 2, z + 6, Blocks.air, 0, 3);
		world.setBlock(x + 0, y + 3, z + 0, PeatizedBlocks.peatStairs, 2, 3);
		world.setBlock(x + 1, y + 3, z + 0, PeatizedBlocks.peatStairs, 2, 3);
		world.setBlock(x + 2, y + 3, z + 0, PeatizedBlocks.peatStairs, 2, 3);
		world.setBlock(x + 3, y + 3, z + 0, PeatizedBlocks.peatStairs, 2, 3);
		world.setBlock(x + 4, y + 3, z + 0, PeatizedBlocks.peatStairs, 2, 3);
		world.setBlock(x + 5, y + 3, z + 0, PeatizedBlocks.peatStairs, 2, 3);
		world.setBlock(x + 6, y + 3, z + 0, PeatizedBlocks.peatStairs, 2, 3);
		world.setBlock(x + 7, y + 3, z + 0, PeatizedBlocks.peatStairs, 2, 3);
		world.setBlock(x + 8, y + 3, z + 0, PeatizedBlocks.peatStairs, 2, 3);
		world.setBlock(x + 9, y + 3, z + 0, PeatizedBlocks.peatStairs, 2, 3);
		world.setBlock(x + 0, y + 3, z + 1, PeatizedBlocks.peatStairs, 7, 3);
		world.setBlock(x + 1, y + 3, z + 1, Blocks.log, 0, 3);
		world.setBlock(x + 2, y + 3, z + 1, Blocks.planks, 0, 3);
		world.setBlock(x + 3, y + 3, z + 1, Blocks.planks, 0, 3);
		world.setBlock(x + 4, y + 3, z + 1, Blocks.planks, 0, 3);
		world.setBlock(x + 5, y + 3, z + 1, Blocks.planks, 0, 3);
		world.setBlock(x + 6, y + 3, z + 1, Blocks.planks, 0, 3);
		world.setBlock(x + 7, y + 3, z + 1, Blocks.planks, 0, 3);
		world.setBlock(x + 8, y + 3, z + 1, Blocks.log, 0, 3);
		world.setBlock(x + 9, y + 3, z + 1, PeatizedBlocks.peatStairs, 7, 3);
		world.setBlock(x + 0, y + 3, z + 2, Blocks.air, 0, 3);
		world.setBlock(x + 1, y + 3, z + 2, PeatizedBlocks.peat, 0, 3);
		world.setBlock(x + 2, y + 3, z + 2, Blocks.air, 0, 3);
		world.setBlock(x + 3, y + 3, z + 2, Blocks.air, 0, 3);
		world.setBlock(x + 4, y + 3, z + 2, Blocks.air, 0, 3);
		world.setBlock(x + 5, y + 3, z + 2, Blocks.air, 0, 3);
		world.setBlock(x + 6, y + 3, z + 2, Blocks.air, 0, 3);
		world.setBlock(x + 7, y + 3, z + 2, Blocks.air, 0, 3);
		world.setBlock(x + 8, y + 3, z + 2, Blocks.planks, 0, 3);
		world.setBlock(x + 9, y + 3, z + 2, Blocks.air, 0, 3);
		world.setBlock(x + 0, y + 3, z + 3, Blocks.air, 0, 3);
		world.setBlock(x + 1, y + 3, z + 3, Blocks.brick_block, 0, 3);
		world.setBlock(x + 2, y + 3, z + 3, Blocks.air, 0, 3);
		world.setBlock(x + 3, y + 3, z + 3, Blocks.air, 0, 3);
		world.setBlock(x + 4, y + 3, z + 3, Blocks.air, 0, 3);
		world.setBlock(x + 5, y + 3, z + 3, Blocks.air, 0, 3);
		world.setBlock(x + 6, y + 3, z + 3, Blocks.air, 0, 3);
		world.setBlock(x + 7, y + 3, z + 3, Blocks.air, 0, 3);
		world.setBlock(x + 8, y + 3, z + 3, Blocks.planks, 0, 3);
		world.setBlock(x + 9, y + 3, z + 3, Blocks.air, 0, 3);
		world.setBlock(x + 0, y + 3, z + 4, Blocks.air, 0, 3);
		world.setBlock(x + 1, y + 3, z + 4, PeatizedBlocks.peat, 0, 3);
		world.setBlock(x + 2, y + 3, z + 4, Blocks.air, 0, 3);
		world.setBlock(x + 3, y + 3, z + 4, Blocks.air, 0, 3);
		world.setBlock(x + 4, y + 3, z + 4, Blocks.air, 0, 3);
		world.setBlock(x + 5, y + 3, z + 4, Blocks.air, 0, 3);
		world.setBlock(x + 6, y + 3, z + 4, Blocks.air, 0, 3);
		world.setBlock(x + 7, y + 3, z + 4, Blocks.air, 0, 3);
		world.setBlock(x + 8, y + 3, z + 4, Blocks.planks, 0, 3);
		world.setBlock(x + 9, y + 3, z + 4, Blocks.air, 0, 3);
		world.setBlock(x + 0, y + 3, z + 5, PeatizedBlocks.peatStairs, 6, 3);
		world.setBlock(x + 1, y + 3, z + 5, Blocks.log, 0, 3);
		world.setBlock(x + 2, y + 3, z + 5, Blocks.planks, 0, 3);
		world.setBlock(x + 3, y + 3, z + 5, Blocks.planks, 0, 3);
		world.setBlock(x + 4, y + 3, z + 5, Blocks.planks, 0, 3);
		world.setBlock(x + 5, y + 3, z + 5, Blocks.planks, 0, 3);
		world.setBlock(x + 6, y + 3, z + 5, Blocks.planks, 0, 3);
		world.setBlock(x + 7, y + 3, z + 5, Blocks.planks, 0, 3);
		world.setBlock(x + 8, y + 3, z + 5, Blocks.log, 0, 3);
		world.setBlock(x + 9, y + 3, z + 5, PeatizedBlocks.peatStairs, 6, 3);
		world.setBlock(x + 0, y + 3, z + 6, PeatizedBlocks.peatStairs, 3, 3);
		world.setBlock(x + 1, y + 3, z + 6, PeatizedBlocks.peatStairs, 3, 3);
		world.setBlock(x + 2, y + 3, z + 6, PeatizedBlocks.peatStairs, 3, 3);
		world.setBlock(x + 3, y + 3, z + 6, PeatizedBlocks.peatStairs, 3, 3);
		world.setBlock(x + 4, y + 3, z + 6, PeatizedBlocks.peatStairs, 3, 3);
		world.setBlock(x + 5, y + 3, z + 6, PeatizedBlocks.peatStairs, 3, 3);
		world.setBlock(x + 6, y + 3, z + 6, PeatizedBlocks.peatStairs, 3, 3);
		world.setBlock(x + 7, y + 3, z + 6, PeatizedBlocks.peatStairs, 3, 3);
		world.setBlock(x + 8, y + 3, z + 6, PeatizedBlocks.peatStairs, 3, 3);
		world.setBlock(x + 9, y + 3, z + 6, PeatizedBlocks.peatStairs, 3, 3);
		world.setBlock(x + 0, y + 4, z + 0, Blocks.air, 0, 3);
		world.setBlock(x + 1, y + 4, z + 0, Blocks.air, 0, 3);
		world.setBlock(x + 2, y + 4, z + 0, Blocks.air, 0, 3);
		world.setBlock(x + 3, y + 4, z + 0, Blocks.air, 0, 3);
		world.setBlock(x + 4, y + 4, z + 0, Blocks.air, 0, 3);
		world.setBlock(x + 5, y + 4, z + 0, Blocks.air, 0, 3);
		world.setBlock(x + 6, y + 4, z + 0, Blocks.air, 0, 3);
		world.setBlock(x + 7, y + 4, z + 0, Blocks.air, 0, 3);
		world.setBlock(x + 8, y + 4, z + 0, Blocks.air, 0, 3);
		world.setBlock(x + 9, y + 4, z + 0, Blocks.air, 0, 3);
		world.setBlock(x + 0, y + 4, z + 1, PeatizedBlocks.peatStairs, 2, 3);
		world.setBlock(x + 1, y + 4, z + 1, PeatizedBlocks.peatStairs, 2, 3);
		world.setBlock(x + 2, y + 4, z + 1, PeatizedBlocks.peatStairs, 2, 3);
		world.setBlock(x + 3, y + 4, z + 1, PeatizedBlocks.peatStairs, 2, 3);
		world.setBlock(x + 4, y + 4, z + 1, PeatizedBlocks.peatStairs, 2, 3);
		world.setBlock(x + 5, y + 4, z + 1, PeatizedBlocks.peatStairs, 2, 3);
		world.setBlock(x + 6, y + 4, z + 1, PeatizedBlocks.peatStairs, 2, 3);
		world.setBlock(x + 7, y + 4, z + 1, PeatizedBlocks.peatStairs, 2, 3);
		world.setBlock(x + 8, y + 4, z + 1, PeatizedBlocks.peatStairs, 2, 3);
		world.setBlock(x + 9, y + 4, z + 1, PeatizedBlocks.peatStairs, 2, 3);
		world.setBlock(x + 0, y + 4, z + 2, PeatizedBlocks.peatStairs, 7, 3);
		world.setBlock(x + 1, y + 4, z + 2, PeatizedBlocks.peat, 0, 3);
		world.setBlock(x + 2, y + 4, z + 2, Blocks.wooden_slab, 8, 3);
		world.setBlock(x + 3, y + 4, z + 2, Blocks.log, 8, 3);
		world.setBlock(x + 4, y + 4, z + 2, Blocks.wooden_slab, 8, 3);
		world.setBlock(x + 5, y + 4, z + 2, Blocks.wooden_slab, 8, 3);
		world.setBlock(x + 6, y + 4, z + 2, Blocks.log, 8, 3);
		world.setBlock(x + 7, y + 4, z + 2, Blocks.wooden_slab, 8, 3);
		world.setBlock(x + 8, y + 4, z + 2, PeatizedBlocks.peat, 0, 3);
		world.setBlock(x + 9, y + 4, z + 2, PeatizedBlocks.peatStairs, 7, 3);
		world.setBlock(x + 0, y + 4, z + 3, Blocks.air, 0, 3);
		world.setBlock(x + 1, y + 4, z + 3, Blocks.brick_block, 0, 3);
		world.setBlock(x + 2, y + 4, z + 3, Blocks.log, 4, 3);
		world.setBlock(x + 3, y + 4, z + 3, Blocks.log, 4, 3);
		world.setBlock(x + 4, y + 4, z + 3, Blocks.log, 4, 3);
		world.setBlock(x + 5, y + 4, z + 3, Blocks.log, 4, 3);
		world.setBlock(x + 6, y + 4, z + 3, Blocks.log, 4, 3);
		world.setBlock(x + 7, y + 4, z + 3, Blocks.log, 4, 3);
		world.setBlock(x + 8, y + 4, z + 3, PeatizedBlocks.peat, 0, 3);
		world.setBlock(x + 9, y + 4, z + 3, Blocks.air, 0, 3);
		world.setBlock(x + 0, y + 4, z + 4, PeatizedBlocks.peatStairs, 6, 3);
		world.setBlock(x + 1, y + 4, z + 4, PeatizedBlocks.peat, 0, 3);
		world.setBlock(x + 2, y + 4, z + 4, Blocks.wooden_slab, 8, 3);
		world.setBlock(x + 3, y + 4, z + 4, Blocks.log, 8, 3);
		world.setBlock(x + 4, y + 4, z + 4, Blocks.wooden_slab, 8, 3);
		world.setBlock(x + 5, y + 4, z + 4, Blocks.wooden_slab, 8, 3);
		world.setBlock(x + 6, y + 4, z + 4, Blocks.log, 8, 3);
		world.setBlock(x + 7, y + 4, z + 4, Blocks.wooden_slab, 8, 3);
		world.setBlock(x + 8, y + 4, z + 4, PeatizedBlocks.peat, 0, 3);
		world.setBlock(x + 9, y + 4, z + 4, PeatizedBlocks.peatStairs, 6, 3);
		world.setBlock(x + 0, y + 4, z + 5, PeatizedBlocks.peatStairs, 3, 3);
		world.setBlock(x + 1, y + 4, z + 5, PeatizedBlocks.peatStairs, 3, 3);
		world.setBlock(x + 2, y + 4, z + 5, PeatizedBlocks.peatStairs, 3, 3);
		world.setBlock(x + 3, y + 4, z + 5, PeatizedBlocks.peatStairs, 3, 3);
		world.setBlock(x + 4, y + 4, z + 5, PeatizedBlocks.peatStairs, 3, 3);
		world.setBlock(x + 5, y + 4, z + 5, PeatizedBlocks.peatStairs, 3, 3);
		world.setBlock(x + 6, y + 4, z + 5, PeatizedBlocks.peatStairs, 3, 3);
		world.setBlock(x + 7, y + 4, z + 5, PeatizedBlocks.peatStairs, 3, 3);
		world.setBlock(x + 8, y + 4, z + 5, PeatizedBlocks.peatStairs, 3, 3);
		world.setBlock(x + 9, y + 4, z + 5, PeatizedBlocks.peatStairs, 3, 3);
		world.setBlock(x + 0, y + 4, z + 6, Blocks.air, 0, 3);
		world.setBlock(x + 1, y + 4, z + 6, Blocks.air, 0, 3);
		world.setBlock(x + 2, y + 4, z + 6, Blocks.air, 0, 3);
		world.setBlock(x + 3, y + 4, z + 6, Blocks.air, 0, 3);
		world.setBlock(x + 4, y + 4, z + 6, Blocks.air, 0, 3);
		world.setBlock(x + 5, y + 4, z + 6, Blocks.air, 0, 3);
		world.setBlock(x + 6, y + 4, z + 6, Blocks.air, 0, 3);
		world.setBlock(x + 7, y + 4, z + 6, Blocks.air, 0, 3);
		world.setBlock(x + 8, y + 4, z + 6, Blocks.air, 0, 3);
		world.setBlock(x + 9, y + 4, z + 6, Blocks.air, 0, 3);
		world.setBlock(x + 0, y + 5, z + 0, Blocks.air, 0, 3);
		world.setBlock(x + 1, y + 5, z + 0, Blocks.air, 0, 3);
		world.setBlock(x + 2, y + 5, z + 0, Blocks.air, 0, 3);
		world.setBlock(x + 3, y + 5, z + 0, Blocks.air, 0, 3);
		world.setBlock(x + 4, y + 5, z + 0, Blocks.air, 0, 3);
		world.setBlock(x + 5, y + 5, z + 0, Blocks.air, 0, 3);
		world.setBlock(x + 6, y + 5, z + 0, Blocks.air, 0, 3);
		world.setBlock(x + 7, y + 5, z + 0, Blocks.air, 0, 3);
		world.setBlock(x + 8, y + 5, z + 0, Blocks.air, 0, 3);
		world.setBlock(x + 9, y + 5, z + 0, Blocks.air, 0, 3);
		world.setBlock(x + 0, y + 5, z + 1, Blocks.air, 0, 3);
		world.setBlock(x + 1, y + 5, z + 1, Blocks.air, 0, 3);
		world.setBlock(x + 2, y + 5, z + 1, Blocks.air, 0, 3);
		world.setBlock(x + 3, y + 5, z + 1, Blocks.air, 0, 3);
		world.setBlock(x + 4, y + 5, z + 1, Blocks.air, 0, 3);
		world.setBlock(x + 5, y + 5, z + 1, Blocks.air, 0, 3);
		world.setBlock(x + 6, y + 5, z + 1, Blocks.air, 0, 3);
		world.setBlock(x + 7, y + 5, z + 1, Blocks.air, 0, 3);
		world.setBlock(x + 8, y + 5, z + 1, Blocks.air, 0, 3);
		world.setBlock(x + 9, y + 5, z + 1, Blocks.air, 0, 3);
		world.setBlock(x + 0, y + 5, z + 2, PeatizedBlocks.peatStairs, 2, 3);
		world.setBlock(x + 1, y + 5, z + 2, PeatizedBlocks.peatStairs, 2, 3);
		world.setBlock(x + 2, y + 5, z + 2, PeatizedBlocks.peatStairs, 2, 3);
		world.setBlock(x + 3, y + 5, z + 2, PeatizedBlocks.peatStairs, 2, 3);
		world.setBlock(x + 4, y + 5, z + 2, PeatizedBlocks.peatStairs, 2, 3);
		world.setBlock(x + 5, y + 5, z + 2, PeatizedBlocks.peatStairs, 2, 3);
		world.setBlock(x + 6, y + 5, z + 2, PeatizedBlocks.peatStairs, 2, 3);
		world.setBlock(x + 7, y + 5, z + 2, PeatizedBlocks.peatStairs, 2, 3);
		world.setBlock(x + 8, y + 5, z + 2, PeatizedBlocks.peatStairs, 2, 3);
		world.setBlock(x + 9, y + 5, z + 2, PeatizedBlocks.peatStairs, 2, 3);
		world.setBlock(x + 0, y + 5, z + 3, PeatizedBlocks.peat, 0, 3);
		world.setBlock(x + 1, y + 5, z + 3, Blocks.brick_block, 0, 3);
		world.setBlock(x + 2, y + 5, z + 3, PeatizedBlocks.peat, 0, 3);
		world.setBlock(x + 3, y + 5, z + 3, PeatizedBlocks.peat, 0, 3);
		world.setBlock(x + 4, y + 5, z + 3, PeatizedBlocks.peat, 0, 3);
		world.setBlock(x + 5, y + 5, z + 3, PeatizedBlocks.peat, 0, 3);
		world.setBlock(x + 6, y + 5, z + 3, PeatizedBlocks.peat, 0, 3);
		world.setBlock(x + 7, y + 5, z + 3, PeatizedBlocks.peat, 0, 3);
		world.setBlock(x + 8, y + 5, z + 3, PeatizedBlocks.peat, 0, 3);
		world.setBlock(x + 9, y + 5, z + 3, PeatizedBlocks.peat, 0, 3);
		world.setBlock(x + 0, y + 5, z + 4, PeatizedBlocks.peatStairs, 3, 3);
		world.setBlock(x + 1, y + 5, z + 4, PeatizedBlocks.peatStairs, 3, 3);
		world.setBlock(x + 2, y + 5, z + 4, PeatizedBlocks.peatStairs, 3, 3);
		world.setBlock(x + 3, y + 5, z + 4, PeatizedBlocks.peatStairs, 3, 3);
		world.setBlock(x + 4, y + 5, z + 4, PeatizedBlocks.peatStairs, 3, 3);
		world.setBlock(x + 5, y + 5, z + 4, PeatizedBlocks.peatStairs, 3, 3);
		world.setBlock(x + 6, y + 5, z + 4, PeatizedBlocks.peatStairs, 3, 3);
		world.setBlock(x + 7, y + 5, z + 4, PeatizedBlocks.peatStairs, 3, 3);
		world.setBlock(x + 8, y + 5, z + 4, PeatizedBlocks.peatStairs, 3, 3);
		world.setBlock(x + 9, y + 5, z + 4, PeatizedBlocks.peatStairs, 3, 3);
		world.setBlock(x + 0, y + 5, z + 5, Blocks.air, 0, 3);
		world.setBlock(x + 1, y + 5, z + 5, Blocks.air, 0, 3);
		world.setBlock(x + 2, y + 5, z + 5, Blocks.air, 0, 3);
		world.setBlock(x + 3, y + 5, z + 5, Blocks.air, 0, 3);
		world.setBlock(x + 4, y + 5, z + 5, Blocks.air, 0, 3);
		world.setBlock(x + 5, y + 5, z + 5, Blocks.air, 0, 3);
		world.setBlock(x + 6, y + 5, z + 5, Blocks.air, 0, 3);
		world.setBlock(x + 7, y + 5, z + 5, Blocks.air, 0, 3);
		world.setBlock(x + 8, y + 5, z + 5, Blocks.air, 0, 3);
		world.setBlock(x + 9, y + 5, z + 5, Blocks.air, 0, 3);
		world.setBlock(x + 0, y + 5, z + 6, Blocks.air, 0, 3);
		world.setBlock(x + 1, y + 5, z + 6, Blocks.air, 0, 3);
		world.setBlock(x + 2, y + 5, z + 6, Blocks.air, 0, 3);
		world.setBlock(x + 3, y + 5, z + 6, Blocks.air, 0, 3);
		world.setBlock(x + 4, y + 5, z + 6, Blocks.air, 0, 3);
		world.setBlock(x + 5, y + 5, z + 6, Blocks.air, 0, 3);
		world.setBlock(x + 6, y + 5, z + 6, Blocks.air, 0, 3);
		world.setBlock(x + 7, y + 5, z + 6, Blocks.air, 0, 3);
		world.setBlock(x + 8, y + 5, z + 6, Blocks.air, 0, 3);
		world.setBlock(x + 9, y + 5, z + 6, Blocks.air, 0, 3);
		world.setBlock(x + 0, y + 6, z + 0, Blocks.air, 0, 3);
		world.setBlock(x + 1, y + 6, z + 0, Blocks.air, 0, 3);
		world.setBlock(x + 2, y + 6, z + 0, Blocks.air, 0, 3);
		world.setBlock(x + 3, y + 6, z + 0, Blocks.air, 0, 3);
		world.setBlock(x + 4, y + 6, z + 0, Blocks.air, 0, 3);
		world.setBlock(x + 5, y + 6, z + 0, Blocks.air, 0, 3);
		world.setBlock(x + 6, y + 6, z + 0, Blocks.air, 0, 3);
		world.setBlock(x + 7, y + 6, z + 0, Blocks.air, 0, 3);
		world.setBlock(x + 8, y + 6, z + 0, Blocks.air, 0, 3);
		world.setBlock(x + 9, y + 6, z + 0, Blocks.air, 0, 3);
		world.setBlock(x + 0, y + 6, z + 1, Blocks.air, 0, 3);
		world.setBlock(x + 1, y + 6, z + 1, Blocks.air, 0, 3);
		world.setBlock(x + 2, y + 6, z + 1, Blocks.air, 0, 3);
		world.setBlock(x + 3, y + 6, z + 1, Blocks.air, 0, 3);
		world.setBlock(x + 4, y + 6, z + 1, Blocks.air, 0, 3);
		world.setBlock(x + 5, y + 6, z + 1, Blocks.air, 0, 3);
		world.setBlock(x + 6, y + 6, z + 1, Blocks.air, 0, 3);
		world.setBlock(x + 7, y + 6, z + 1, Blocks.air, 0, 3);
		world.setBlock(x + 8, y + 6, z + 1, Blocks.air, 0, 3);
		world.setBlock(x + 9, y + 6, z + 1, Blocks.air, 0, 3);
		world.setBlock(x + 0, y + 6, z + 2, Blocks.air, 0, 3);
		world.setBlock(x + 1, y + 6, z + 2, Blocks.air, 0, 3);
		world.setBlock(x + 2, y + 6, z + 2, Blocks.air, 0, 3);
		world.setBlock(x + 3, y + 6, z + 2, Blocks.air, 0, 3);
		world.setBlock(x + 4, y + 6, z + 2, Blocks.air, 0, 3);
		world.setBlock(x + 5, y + 6, z + 2, Blocks.air, 0, 3);
		world.setBlock(x + 6, y + 6, z + 2, Blocks.air, 0, 3);
		world.setBlock(x + 7, y + 6, z + 2, Blocks.air, 0, 3);
		world.setBlock(x + 8, y + 6, z + 2, Blocks.air, 0, 3);
		world.setBlock(x + 9, y + 6, z + 2, Blocks.air, 0, 3);
		world.setBlock(x + 0, y + 6, z + 3, PeatizedBlocks.peatSlab, 0, 3);
		world.setBlock(x + 1, y + 6, z + 3, Blocks.brick_block, 0, 3);
		world.setBlock(x + 2, y + 6, z + 3, PeatizedBlocks.peatSlab, 0, 3);
		world.setBlock(x + 3, y + 6, z + 3, PeatizedBlocks.peatSlab, 0, 3);
		world.setBlock(x + 4, y + 6, z + 3, PeatizedBlocks.peatSlab, 0, 3);
		world.setBlock(x + 5, y + 6, z + 3, PeatizedBlocks.peatSlab, 0, 3);
		world.setBlock(x + 6, y + 6, z + 3, PeatizedBlocks.peatSlab, 0, 3);
		world.setBlock(x + 7, y + 6, z + 3, PeatizedBlocks.peatSlab, 0, 3);
		world.setBlock(x + 8, y + 6, z + 3, PeatizedBlocks.peatSlab, 0, 3);
		world.setBlock(x + 9, y + 6, z + 3, PeatizedBlocks.peatSlab, 0, 3);
		world.setBlock(x + 0, y + 6, z + 4, Blocks.air, 0, 3);
		world.setBlock(x + 1, y + 6, z + 4, Blocks.air, 0, 3);
		world.setBlock(x + 2, y + 6, z + 4, Blocks.air, 0, 3);
		world.setBlock(x + 3, y + 6, z + 4, Blocks.air, 0, 3);
		world.setBlock(x + 4, y + 6, z + 4, Blocks.air, 0, 3);
		world.setBlock(x + 5, y + 6, z + 4, Blocks.air, 0, 3);
		world.setBlock(x + 6, y + 6, z + 4, Blocks.air, 0, 3);
		world.setBlock(x + 7, y + 6, z + 4, Blocks.air, 0, 3);
		world.setBlock(x + 8, y + 6, z + 4, Blocks.air, 0, 3);
		world.setBlock(x + 9, y + 6, z + 4, Blocks.air, 0, 3);
		world.setBlock(x + 0, y + 6, z + 5, Blocks.air, 0, 3);
		world.setBlock(x + 1, y + 6, z + 5, Blocks.air, 0, 3);
		world.setBlock(x + 2, y + 6, z + 5, Blocks.air, 0, 3);
		world.setBlock(x + 3, y + 6, z + 5, Blocks.air, 0, 3);
		world.setBlock(x + 4, y + 6, z + 5, Blocks.air, 0, 3);
		world.setBlock(x + 5, y + 6, z + 5, Blocks.air, 0, 3);
		world.setBlock(x + 6, y + 6, z + 5, Blocks.air, 0, 3);
		world.setBlock(x + 7, y + 6, z + 5, Blocks.air, 0, 3);
		world.setBlock(x + 8, y + 6, z + 5, Blocks.air, 0, 3);
		world.setBlock(x + 9, y + 6, z + 5, Blocks.air, 0, 3);
		world.setBlock(x + 0, y + 6, z + 6, Blocks.air, 0, 3);
		world.setBlock(x + 1, y + 6, z + 6, Blocks.air, 0, 3);
		world.setBlock(x + 2, y + 6, z + 6, Blocks.air, 0, 3);
		world.setBlock(x + 3, y + 6, z + 6, Blocks.air, 0, 3);
		world.setBlock(x + 4, y + 6, z + 6, Blocks.air, 0, 3);
		world.setBlock(x + 5, y + 6, z + 6, Blocks.air, 0, 3);
		world.setBlock(x + 6, y + 6, z + 6, Blocks.air, 0, 3);
		world.setBlock(x + 7, y + 6, z + 6, Blocks.air, 0, 3);
		world.setBlock(x + 8, y + 6, z + 6, Blocks.air, 0, 3);
		world.setBlock(x + 9, y + 6, z + 6, Blocks.air, 0, 3);
		world.setBlock(x + 0, y + 7, z + 0, Blocks.air, 0, 3);
		world.setBlock(x + 1, y + 7, z + 0, Blocks.air, 0, 3);
		world.setBlock(x + 2, y + 7, z + 0, Blocks.air, 0, 3);
		world.setBlock(x + 3, y + 7, z + 0, Blocks.air, 0, 3);
		world.setBlock(x + 4, y + 7, z + 0, Blocks.air, 0, 3);
		world.setBlock(x + 5, y + 7, z + 0, Blocks.air, 0, 3);
		world.setBlock(x + 6, y + 7, z + 0, Blocks.air, 0, 3);
		world.setBlock(x + 7, y + 7, z + 0, Blocks.air, 0, 3);
		world.setBlock(x + 8, y + 7, z + 0, Blocks.air, 0, 3);
		world.setBlock(x + 9, y + 7, z + 0, Blocks.air, 0, 3);
		world.setBlock(x + 0, y + 7, z + 1, Blocks.air, 0, 3);
		world.setBlock(x + 1, y + 7, z + 1, Blocks.air, 0, 3);
		world.setBlock(x + 2, y + 7, z + 1, Blocks.air, 0, 3);
		world.setBlock(x + 3, y + 7, z + 1, Blocks.air, 0, 3);
		world.setBlock(x + 4, y + 7, z + 1, Blocks.air, 0, 3);
		world.setBlock(x + 5, y + 7, z + 1, Blocks.air, 0, 3);
		world.setBlock(x + 6, y + 7, z + 1, Blocks.air, 0, 3);
		world.setBlock(x + 7, y + 7, z + 1, Blocks.air, 0, 3);
		world.setBlock(x + 8, y + 7, z + 1, Blocks.air, 0, 3);
		world.setBlock(x + 9, y + 7, z + 1, Blocks.air, 0, 3);
		world.setBlock(x + 0, y + 7, z + 2, Blocks.air, 0, 3);
		world.setBlock(x + 1, y + 7, z + 2, Blocks.air, 0, 3);
		world.setBlock(x + 2, y + 7, z + 2, Blocks.air, 0, 3);
		world.setBlock(x + 3, y + 7, z + 2, Blocks.air, 0, 3);
		world.setBlock(x + 4, y + 7, z + 2, Blocks.air, 0, 3);
		world.setBlock(x + 5, y + 7, z + 2, Blocks.air, 0, 3);
		world.setBlock(x + 6, y + 7, z + 2, Blocks.air, 0, 3);
		world.setBlock(x + 7, y + 7, z + 2, Blocks.air, 0, 3);
		world.setBlock(x + 8, y + 7, z + 2, Blocks.air, 0, 3);
		world.setBlock(x + 9, y + 7, z + 2, Blocks.air, 0, 3);
		world.setBlock(x + 0, y + 7, z + 3, Blocks.air, 0, 3);
		world.setBlock(x + 1, y + 7, z + 3, Blocks.cobblestone_wall, 0, 3);
		world.setBlock(x + 2, y + 7, z + 3, Blocks.air, 0, 3);
		world.setBlock(x + 3, y + 7, z + 3, Blocks.air, 0, 3);
		world.setBlock(x + 4, y + 7, z + 3, Blocks.air, 0, 3);
		world.setBlock(x + 5, y + 7, z + 3, Blocks.air, 0, 3);
		world.setBlock(x + 6, y + 7, z + 3, Blocks.air, 0, 3);
		world.setBlock(x + 7, y + 7, z + 3, Blocks.air, 0, 3);
		world.setBlock(x + 8, y + 7, z + 3, Blocks.air, 0, 3);
		world.setBlock(x + 9, y + 7, z + 3, Blocks.air, 0, 3);
		world.setBlock(x + 0, y + 7, z + 4, Blocks.air, 0, 3);
		world.setBlock(x + 1, y + 7, z + 4, Blocks.air, 0, 3);
		world.setBlock(x + 2, y + 7, z + 4, Blocks.air, 0, 3);
		world.setBlock(x + 3, y + 7, z + 4, Blocks.air, 0, 3);
		world.setBlock(x + 4, y + 7, z + 4, Blocks.air, 0, 3);
		world.setBlock(x + 5, y + 7, z + 4, Blocks.air, 0, 3);
		world.setBlock(x + 6, y + 7, z + 4, Blocks.air, 0, 3);
		world.setBlock(x + 7, y + 7, z + 4, Blocks.air, 0, 3);
		world.setBlock(x + 8, y + 7, z + 4, Blocks.air, 0, 3);
		world.setBlock(x + 9, y + 7, z + 4, Blocks.air, 0, 3);
		world.setBlock(x + 0, y + 7, z + 5, Blocks.air, 0, 3);
		world.setBlock(x + 1, y + 7, z + 5, Blocks.air, 0, 3);
		world.setBlock(x + 2, y + 7, z + 5, Blocks.air, 0, 3);
		world.setBlock(x + 3, y + 7, z + 5, Blocks.air, 0, 3);
		world.setBlock(x + 4, y + 7, z + 5, Blocks.air, 0, 3);
		world.setBlock(x + 5, y + 7, z + 5, Blocks.air, 0, 3);
		world.setBlock(x + 6, y + 7, z + 5, Blocks.air, 0, 3);
		world.setBlock(x + 7, y + 7, z + 5, Blocks.air, 0, 3);
		world.setBlock(x + 8, y + 7, z + 5, Blocks.air, 0, 3);
		world.setBlock(x + 9, y + 7, z + 5, Blocks.air, 0, 3);
		world.setBlock(x + 0, y + 7, z + 6, Blocks.air, 0, 3);
		world.setBlock(x + 1, y + 7, z + 6, Blocks.air, 0, 3);
		world.setBlock(x + 2, y + 7, z + 6, Blocks.air, 0, 3);
		world.setBlock(x + 3, y + 7, z + 6, Blocks.air, 0, 3);
		world.setBlock(x + 4, y + 7, z + 6, Blocks.air, 0, 3);
		world.setBlock(x + 5, y + 7, z + 6, Blocks.air, 0, 3);
		world.setBlock(x + 6, y + 7, z + 6, Blocks.air, 0, 3);
		world.setBlock(x + 7, y + 7, z + 6, Blocks.air, 0, 3);
		world.setBlock(x + 8, y + 7, z + 6, Blocks.air, 0, 3);
		world.setBlock(x + 9, y + 7, z + 6, Blocks.air, 0, 3);
		world.setBlock(x + 0, y + 8, z + 0, Blocks.air, 0, 3);
		world.setBlock(x + 1, y + 8, z + 0, Blocks.air, 0, 3);
		world.setBlock(x + 2, y + 8, z + 0, Blocks.air, 0, 3);
		world.setBlock(x + 3, y + 8, z + 0, Blocks.air, 0, 3);
		world.setBlock(x + 4, y + 8, z + 0, Blocks.air, 0, 3);
		world.setBlock(x + 5, y + 8, z + 0, Blocks.air, 0, 3);
		world.setBlock(x + 6, y + 8, z + 0, Blocks.air, 0, 3);
		world.setBlock(x + 7, y + 8, z + 0, Blocks.air, 0, 3);
		world.setBlock(x + 8, y + 8, z + 0, Blocks.air, 0, 3);
		world.setBlock(x + 9, y + 8, z + 0, Blocks.air, 0, 3);
		world.setBlock(x + 0, y + 8, z + 1, Blocks.air, 0, 3);
		world.setBlock(x + 1, y + 8, z + 1, Blocks.air, 0, 3);
		world.setBlock(x + 2, y + 8, z + 1, Blocks.air, 0, 3);
		world.setBlock(x + 3, y + 8, z + 1, Blocks.air, 0, 3);
		world.setBlock(x + 4, y + 8, z + 1, Blocks.air, 0, 3);
		world.setBlock(x + 5, y + 8, z + 1, Blocks.air, 0, 3);
		world.setBlock(x + 6, y + 8, z + 1, Blocks.air, 0, 3);
		world.setBlock(x + 7, y + 8, z + 1, Blocks.air, 0, 3);
		world.setBlock(x + 8, y + 8, z + 1, Blocks.air, 0, 3);
		world.setBlock(x + 9, y + 8, z + 1, Blocks.air, 0, 3);
		world.setBlock(x + 0, y + 8, z + 2, Blocks.air, 0, 3);
		world.setBlock(x + 1, y + 8, z + 2, Blocks.air, 0, 3);
		world.setBlock(x + 2, y + 8, z + 2, Blocks.air, 0, 3);
		world.setBlock(x + 3, y + 8, z + 2, Blocks.air, 0, 3);
		world.setBlock(x + 4, y + 8, z + 2, Blocks.air, 0, 3);
		world.setBlock(x + 5, y + 8, z + 2, Blocks.air, 0, 3);
		world.setBlock(x + 6, y + 8, z + 2, Blocks.air, 0, 3);
		world.setBlock(x + 7, y + 8, z + 2, Blocks.air, 0, 3);
		world.setBlock(x + 8, y + 8, z + 2, Blocks.air, 0, 3);
		world.setBlock(x + 9, y + 8, z + 2, Blocks.air, 0, 3);
		world.setBlock(x + 0, y + 8, z + 3, Blocks.air, 0, 3);
		world.setBlock(x + 1, y + 8, z + 3, Blocks.stone_slab, 4, 3);
		world.setBlock(x + 2, y + 8, z + 3, Blocks.air, 0, 3);
		world.setBlock(x + 3, y + 8, z + 3, Blocks.air, 0, 3);
		world.setBlock(x + 4, y + 8, z + 3, Blocks.air, 0, 3);
		world.setBlock(x + 5, y + 8, z + 3, Blocks.air, 0, 3);
		world.setBlock(x + 6, y + 8, z + 3, Blocks.air, 0, 3);
		world.setBlock(x + 7, y + 8, z + 3, Blocks.air, 0, 3);
		world.setBlock(x + 8, y + 8, z + 3, Blocks.air, 0, 3);
		world.setBlock(x + 9, y + 8, z + 3, Blocks.air, 0, 3);
		world.setBlock(x + 0, y + 8, z + 4, Blocks.air, 0, 3);
		world.setBlock(x + 1, y + 8, z + 4, Blocks.air, 0, 3);
		world.setBlock(x + 2, y + 8, z + 4, Blocks.air, 0, 3);
		world.setBlock(x + 3, y + 8, z + 4, Blocks.air, 0, 3);
		world.setBlock(x + 4, y + 8, z + 4, Blocks.air, 0, 3);
		world.setBlock(x + 5, y + 8, z + 4, Blocks.air, 0, 3);
		world.setBlock(x + 6, y + 8, z + 4, Blocks.air, 0, 3);
		world.setBlock(x + 7, y + 8, z + 4, Blocks.air, 0, 3);
		world.setBlock(x + 8, y + 8, z + 4, Blocks.air, 0, 3);
		world.setBlock(x + 9, y + 8, z + 4, Blocks.air, 0, 3);
		world.setBlock(x + 0, y + 8, z + 5, Blocks.air, 0, 3);
		world.setBlock(x + 1, y + 8, z + 5, Blocks.air, 0, 3);
		world.setBlock(x + 2, y + 8, z + 5, Blocks.air, 0, 3);
		world.setBlock(x + 3, y + 8, z + 5, Blocks.air, 0, 3);
		world.setBlock(x + 4, y + 8, z + 5, Blocks.air, 0, 3);
		world.setBlock(x + 5, y + 8, z + 5, Blocks.air, 0, 3);
		world.setBlock(x + 6, y + 8, z + 5, Blocks.air, 0, 3);
		world.setBlock(x + 7, y + 8, z + 5, Blocks.air, 0, 3);
		world.setBlock(x + 8, y + 8, z + 5, Blocks.air, 0, 3);
		world.setBlock(x + 9, y + 8, z + 5, Blocks.air, 0, 3);
		world.setBlock(x + 0, y + 8, z + 6, Blocks.air, 0, 3);
		world.setBlock(x + 1, y + 8, z + 6, Blocks.air, 0, 3);
		world.setBlock(x + 2, y + 8, z + 6, Blocks.air, 0, 3);
		world.setBlock(x + 3, y + 8, z + 6, Blocks.air, 0, 3);
		world.setBlock(x + 4, y + 8, z + 6, Blocks.air, 0, 3);
		world.setBlock(x + 5, y + 8, z + 6, Blocks.air, 0, 3);
		world.setBlock(x + 6, y + 8, z + 6, Blocks.air, 0, 3);
		world.setBlock(x + 7, y + 8, z + 6, Blocks.air, 0, 3);
		world.setBlock(x + 8, y + 8, z + 6, Blocks.air, 0, 3);
		world.setBlock(x + 9, y + 8, z + 6, Blocks.air, 0, 3);
		return generateR02Last(world, rand, x, y, z);

	}

	public boolean generateR02Last(World world, Random rand, int x, int y, int z) {
		world.setBlock(x + 5, y + 2, z + 4, Blocks.torch, 4, 3);
		world.setBlock(x + 5, y + 2, z + 6, Blocks.torch, 3, 3);
		world.setBlock(x + 6, y + 1, z + 5, Blocks.wooden_door, 3, 3);
		world.setBlock(x + 6, y + 2, z + 5, Blocks.wooden_door, 8, 3);
		world.setBlock(x + 1, y + 1, z + 3, Blocks.furnace, 0, 3);
		world.setBlock(x + 7, y + 1, z + 3, Blocks.chest, 0, 3);
		boolean flag = generateChest(world, rand, x + 7, y + 1, z + 3);
		world.setBlock(x + 7, y + 1, z + 2, Blocks.crafting_table, 0, 3);
		boolean flag1 = generateVillager(world, rand, x + 6, y + 1, z + 2);
		world.setBlock(x + 4, y + 1, z + 2, Blocks.bed, 9, 3);
		world.setBlock(x + 5, y + 1, z + 2, Blocks.bed, 1, 3);
		return flag && flag1;
	}

	public boolean generateR1(World world, Random rand, int x, int y, int z) {
		if (!canGenerateLocal(world, x, y, z, x + 6, z + 9)) {
			return false;
		}
		world.setBlock(x + 0, y + -1, z + 9, Blocks.cobblestone, 0, 3);
		world.setBlock(x + 0, y + -1, z + 8, Blocks.cobblestone, 0, 3);
		world.setBlock(x + 0, y + -1, z + 7, Blocks.cobblestone, 0, 3);
		world.setBlock(x + 0, y + -1, z + 6, Blocks.cobblestone, 0, 3);
		world.setBlock(x + 0, y + -1, z + 5, Blocks.cobblestone, 0, 3);
		world.setBlock(x + 0, y + -1, z + 4, Blocks.cobblestone, 0, 3);
		world.setBlock(x + 0, y + -1, z + 3, Blocks.cobblestone, 0, 3);
		world.setBlock(x + 0, y + -1, z + 2, Blocks.cobblestone, 0, 3);
		world.setBlock(x + 0, y + -1, z + 1, Blocks.cobblestone, 0, 3);
		world.setBlock(x + 0, y + -1, z + 0, Blocks.cobblestone, 0, 3);
		world.setBlock(x + 1, y + -1, z + 9, Blocks.cobblestone, 0, 3);
		world.setBlock(x + 1, y + -1, z + 8, Blocks.cobblestone, 0, 3);
		world.setBlock(x + 1, y + -1, z + 7, Blocks.cobblestone, 0, 3);
		world.setBlock(x + 1, y + -1, z + 6, Blocks.cobblestone, 0, 3);
		world.setBlock(x + 1, y + -1, z + 5, Blocks.cobblestone, 0, 3);
		world.setBlock(x + 1, y + -1, z + 4, Blocks.cobblestone, 0, 3);
		world.setBlock(x + 1, y + -1, z + 3, Blocks.cobblestone, 0, 3);
		world.setBlock(x + 1, y + -1, z + 2, Blocks.cobblestone, 0, 3);
		world.setBlock(x + 1, y + -1, z + 1, Blocks.cobblestone, 0, 3);
		world.setBlock(x + 1, y + -1, z + 0, Blocks.cobblestone, 0, 3);
		world.setBlock(x + 2, y + -1, z + 9, Blocks.cobblestone, 0, 3);
		world.setBlock(x + 2, y + -1, z + 8, Blocks.cobblestone, 0, 3);
		world.setBlock(x + 2, y + -1, z + 7, Blocks.cobblestone, 0, 3);
		world.setBlock(x + 2, y + -1, z + 6, Blocks.cobblestone, 0, 3);
		world.setBlock(x + 2, y + -1, z + 5, Blocks.cobblestone, 0, 3);
		world.setBlock(x + 2, y + -1, z + 4, Blocks.cobblestone, 0, 3);
		world.setBlock(x + 2, y + -1, z + 3, Blocks.cobblestone, 0, 3);
		world.setBlock(x + 2, y + -1, z + 2, Blocks.cobblestone, 0, 3);
		world.setBlock(x + 2, y + -1, z + 1, Blocks.cobblestone, 0, 3);
		world.setBlock(x + 2, y + -1, z + 0, Blocks.cobblestone, 0, 3);
		world.setBlock(x + 3, y + -1, z + 9, Blocks.cobblestone, 0, 3);
		world.setBlock(x + 3, y + -1, z + 8, Blocks.cobblestone, 0, 3);
		world.setBlock(x + 3, y + -1, z + 7, Blocks.cobblestone, 0, 3);
		world.setBlock(x + 3, y + -1, z + 6, Blocks.cobblestone, 0, 3);
		world.setBlock(x + 3, y + -1, z + 5, Blocks.cobblestone, 0, 3);
		world.setBlock(x + 3, y + -1, z + 4, Blocks.cobblestone, 0, 3);
		world.setBlock(x + 3, y + -1, z + 3, Blocks.cobblestone, 0, 3);
		world.setBlock(x + 3, y + -1, z + 2, Blocks.cobblestone, 0, 3);
		world.setBlock(x + 3, y + -1, z + 1, Blocks.cobblestone, 0, 3);
		world.setBlock(x + 3, y + -1, z + 0, Blocks.cobblestone, 0, 3);
		world.setBlock(x + 4, y + -1, z + 9, Blocks.cobblestone, 0, 3);
		world.setBlock(x + 4, y + -1, z + 8, Blocks.cobblestone, 0, 3);
		world.setBlock(x + 4, y + -1, z + 7, Blocks.cobblestone, 0, 3);
		world.setBlock(x + 4, y + -1, z + 6, Blocks.cobblestone, 0, 3);
		world.setBlock(x + 4, y + -1, z + 5, Blocks.cobblestone, 0, 3);
		world.setBlock(x + 4, y + -1, z + 4, Blocks.cobblestone, 0, 3);
		world.setBlock(x + 4, y + -1, z + 3, Blocks.cobblestone, 0, 3);
		world.setBlock(x + 4, y + -1, z + 2, Blocks.cobblestone, 0, 3);
		world.setBlock(x + 4, y + -1, z + 1, Blocks.cobblestone, 0, 3);
		world.setBlock(x + 4, y + -1, z + 0, Blocks.cobblestone, 0, 3);
		world.setBlock(x + 5, y + -1, z + 9, Blocks.cobblestone, 0, 3);
		world.setBlock(x + 5, y + -1, z + 8, Blocks.cobblestone, 0, 3);
		world.setBlock(x + 5, y + -1, z + 7, Blocks.cobblestone, 0, 3);
		world.setBlock(x + 5, y + -1, z + 6, Blocks.cobblestone, 0, 3);
		world.setBlock(x + 5, y + -1, z + 5, Blocks.cobblestone, 0, 3);
		world.setBlock(x + 5, y + -1, z + 4, Blocks.cobblestone, 0, 3);
		world.setBlock(x + 5, y + -1, z + 3, Blocks.cobblestone, 0, 3);
		world.setBlock(x + 5, y + -1, z + 2, Blocks.cobblestone, 0, 3);
		world.setBlock(x + 5, y + -1, z + 1, Blocks.cobblestone, 0, 3);
		world.setBlock(x + 5, y + -1, z + 0, Blocks.cobblestone, 0, 3);
		world.setBlock(x + 6, y + -1, z + 9, Blocks.cobblestone, 0, 3);
		world.setBlock(x + 6, y + -1, z + 8, Blocks.cobblestone, 0, 3);
		world.setBlock(x + 6, y + -1, z + 7, Blocks.cobblestone, 0, 3);
		world.setBlock(x + 6, y + -1, z + 6, Blocks.cobblestone, 0, 3);
		world.setBlock(x + 6, y + -1, z + 5, Blocks.cobblestone, 0, 3);
		world.setBlock(x + 6, y + -1, z + 4, Blocks.cobblestone, 0, 3);
		world.setBlock(x + 6, y + -1, z + 3, Blocks.cobblestone, 0, 3);
		world.setBlock(x + 6, y + -1, z + 2, Blocks.cobblestone, 0, 3);
		world.setBlock(x + 6, y + -1, z + 1, Blocks.cobblestone, 0, 3);
		world.setBlock(x + 6, y + -1, z + 0, Blocks.cobblestone, 0, 3);
		world.setBlock(x + 0, y + 0, z + 9, Blocks.air, 0, 3);
		world.setBlock(x + 0, y + 0, z + 8, Blocks.air, 0, 3);
		world.setBlock(x + 0, y + 0, z + 7, Blocks.air, 0, 3);
		world.setBlock(x + 0, y + 0, z + 6, Blocks.air, 0, 3);
		world.setBlock(x + 0, y + 0, z + 5, Blocks.air, 0, 3);
		world.setBlock(x + 0, y + 0, z + 4, Blocks.air, 0, 3);
		world.setBlock(x + 0, y + 0, z + 3, Blocks.air, 0, 3);
		world.setBlock(x + 0, y + 0, z + 2, Blocks.air, 0, 3);
		world.setBlock(x + 0, y + 0, z + 1, Blocks.air, 0, 3);
		world.setBlock(x + 0, y + 0, z + 0, Blocks.air, 0, 3);
		world.setBlock(x + 1, y + 0, z + 9, Blocks.air, 0, 3);
		world.setBlock(x + 1, y + 0, z + 8, PeatizedBlocks.peat, 0, 3);
		world.setBlock(x + 1, y + 0, z + 7, PeatizedBlocks.peat, 0, 3);
		world.setBlock(x + 1, y + 0, z + 6, PeatizedBlocks.peat, 0, 3);
		world.setBlock(x + 1, y + 0, z + 5, PeatizedBlocks.peat, 0, 3);
		world.setBlock(x + 1, y + 0, z + 4, PeatizedBlocks.peat, 0, 3);
		world.setBlock(x + 1, y + 0, z + 3, PeatizedBlocks.peat, 0, 3);
		world.setBlock(x + 1, y + 0, z + 2, PeatizedBlocks.peat, 0, 3);
		world.setBlock(x + 1, y + 0, z + 1, Blocks.log, 0, 3);
		world.setBlock(x + 1, y + 0, z + 0, Blocks.air, 0, 3);
		world.setBlock(x + 2, y + 0, z + 9, Blocks.brick_block, 0, 3);
		world.setBlock(x + 2, y + 0, z + 8, Blocks.brick_block, 0, 3);
		world.setBlock(x + 2, y + 0, z + 7, Blocks.brick_block, 0, 3);
		world.setBlock(x + 2, y + 0, z + 6, PeatizedBlocks.peat, 0, 3);
		world.setBlock(x + 2, y + 0, z + 5, PeatizedBlocks.peat, 0, 3);
		world.setBlock(x + 2, y + 0, z + 4, PeatizedBlocks.peat, 0, 3);
		world.setBlock(x + 2, y + 0, z + 3, PeatizedBlocks.peat, 0, 3);
		world.setBlock(x + 2, y + 0, z + 2, PeatizedBlocks.peat, 0, 3);
		world.setBlock(x + 2, y + 0, z + 1, PeatizedBlocks.peat, 0, 3);
		world.setBlock(x + 2, y + 0, z + 0, Blocks.air, 0, 3);
		world.setBlock(x + 3, y + 0, z + 9, Blocks.brick_block, 0, 3);
		world.setBlock(x + 3, y + 0, z + 8, Blocks.brick_block, 0, 3);
		world.setBlock(x + 3, y + 0, z + 7, Blocks.brick_block, 0, 3);
		world.setBlock(x + 3, y + 0, z + 6, PeatizedBlocks.peat, 0, 3);
		world.setBlock(x + 3, y + 0, z + 5, PeatizedBlocks.peat, 0, 3);
		world.setBlock(x + 3, y + 0, z + 4, PeatizedBlocks.peat, 0, 3);
		world.setBlock(x + 3, y + 0, z + 3, PeatizedBlocks.peat, 0, 3);
		world.setBlock(x + 3, y + 0, z + 2, PeatizedBlocks.peat, 0, 3);
		world.setBlock(x + 3, y + 0, z + 1, PeatizedBlocks.peat, 0, 3);
		world.setBlock(x + 3, y + 0, z + 0, Blocks.air, 0, 3);
		world.setBlock(x + 4, y + 0, z + 9, Blocks.brick_block, 0, 3);
		world.setBlock(x + 4, y + 0, z + 8, Blocks.brick_block, 0, 3);
		world.setBlock(x + 4, y + 0, z + 7, Blocks.brick_block, 0, 3);
		world.setBlock(x + 4, y + 0, z + 6, PeatizedBlocks.peat, 0, 3);
		world.setBlock(x + 4, y + 0, z + 5, PeatizedBlocks.peat, 0, 3);
		world.setBlock(x + 4, y + 0, z + 4, PeatizedBlocks.peat, 0, 3);
		world.setBlock(x + 4, y + 0, z + 3, PeatizedBlocks.peat, 0, 3);
		world.setBlock(x + 4, y + 0, z + 2, PeatizedBlocks.peat, 0, 3);
		world.setBlock(x + 4, y + 0, z + 1, PeatizedBlocks.peat, 0, 3);
		world.setBlock(x + 4, y + 0, z + 0, Blocks.air, 0, 3);
		world.setBlock(x + 5, y + 0, z + 9, Blocks.air, 0, 3);
		world.setBlock(x + 5, y + 0, z + 8, PeatizedBlocks.peat, 0, 3);
		world.setBlock(x + 5, y + 0, z + 7, PeatizedBlocks.peat, 0, 3);
		world.setBlock(x + 5, y + 0, z + 6, PeatizedBlocks.peat, 0, 3);
		world.setBlock(x + 5, y + 0, z + 5, PeatizedBlocks.peat, 0, 3);
		world.setBlock(x + 5, y + 0, z + 4, PeatizedBlocks.peat, 0, 3);
		world.setBlock(x + 5, y + 0, z + 3, PeatizedBlocks.peat, 0, 3);
		world.setBlock(x + 5, y + 0, z + 2, PeatizedBlocks.peat, 0, 3);
		world.setBlock(x + 5, y + 0, z + 1, Blocks.log, 0, 3);
		world.setBlock(x + 5, y + 0, z + 0, Blocks.air, 0, 3);
		world.setBlock(x + 6, y + 0, z + 9, Blocks.air, 0, 3);
		world.setBlock(x + 6, y + 0, z + 8, Blocks.air, 0, 3);
		world.setBlock(x + 6, y + 0, z + 7, Blocks.air, 0, 3);
		world.setBlock(x + 6, y + 0, z + 6, Blocks.air, 0, 3);
		world.setBlock(x + 6, y + 0, z + 5, Blocks.air, 0, 3);
		world.setBlock(x + 6, y + 0, z + 4, Blocks.air, 0, 3);
		world.setBlock(x + 6, y + 0, z + 3, Blocks.air, 0, 3);
		world.setBlock(x + 6, y + 0, z + 2, Blocks.air, 0, 3);
		world.setBlock(x + 6, y + 0, z + 1, Blocks.air, 0, 3);
		world.setBlock(x + 6, y + 0, z + 0, Blocks.air, 0, 3);
		world.setBlock(x + 0, y + 1, z + 9, Blocks.air, 0, 3);
		world.setBlock(x + 0, y + 1, z + 8, Blocks.air, 0, 3);
		world.setBlock(x + 0, y + 1, z + 7, Blocks.air, 0, 3);
		world.setBlock(x + 0, y + 1, z + 6, Blocks.air, 0, 3);
		world.setBlock(x + 0, y + 1, z + 5, Blocks.air, 0, 3);
		world.setBlock(x + 0, y + 1, z + 4, Blocks.air, 0, 3);
		world.setBlock(x + 0, y + 1, z + 3, Blocks.air, 0, 3);
		world.setBlock(x + 0, y + 1, z + 2, Blocks.air, 0, 3);
		world.setBlock(x + 0, y + 1, z + 1, Blocks.air, 0, 3);
		world.setBlock(x + 0, y + 1, z + 0, Blocks.air, 0, 3);
		world.setBlock(x + 1, y + 1, z + 9, Blocks.air, 0, 3);
		world.setBlock(x + 1, y + 1, z + 8, Blocks.log, 0, 3);
		world.setBlock(x + 1, y + 1, z + 7, Blocks.planks, 0, 3);
		world.setBlock(x + 1, y + 1, z + 6, Blocks.planks, 0, 3);
		world.setBlock(x + 1, y + 1, z + 5, Blocks.planks, 0, 3);
		world.setBlock(x + 1, y + 1, z + 4, Blocks.planks, 0, 3);
		world.setBlock(x + 1, y + 1, z + 3, Blocks.planks, 0, 3);
		world.setBlock(x + 1, y + 1, z + 2, Blocks.planks, 0, 3);
		world.setBlock(x + 1, y + 1, z + 1, Blocks.log, 0, 3);
		world.setBlock(x + 1, y + 1, z + 0, Blocks.air, 0, 3);
		world.setBlock(x + 2, y + 1, z + 9, Blocks.brick_stairs, 3, 3);
		world.setBlock(x + 2, y + 1, z + 8, Blocks.brick_block, 0, 3);
		world.setBlock(x + 2, y + 1, z + 7, Blocks.brick_stairs, 2, 3);
		world.setBlock(x + 2, y + 1, z + 6, Blocks.air, 0, 3);
		world.setBlock(x + 2, y + 1, z + 3, Blocks.air, 0, 3);
		world.setBlock(x + 2, y + 1, z + 1, Blocks.planks, 0, 3);
		world.setBlock(x + 2, y + 1, z + 0, Blocks.air, 0, 3);
		world.setBlock(x + 3, y + 1, z + 9, Blocks.brick_block, 0, 3);
		world.setBlock(x + 3, y + 1, z + 7, Blocks.air, 0, 3);
		world.setBlock(x + 3, y + 1, z + 6, Blocks.air, 0, 3);
		world.setBlock(x + 3, y + 1, z + 5, Blocks.air, 0, 3);
		world.setBlock(x + 3, y + 1, z + 4, Blocks.air, 0, 3);
		world.setBlock(x + 3, y + 1, z + 3, Blocks.air, 0, 3);
		world.setBlock(x + 3, y + 1, z + 1, Blocks.planks, 0, 3);
		world.setBlock(x + 3, y + 1, z + 0, Blocks.air, 0, 3);
		world.setBlock(x + 4, y + 1, z + 9, Blocks.brick_stairs, 3, 3);
		world.setBlock(x + 4, y + 1, z + 8, Blocks.brick_block, 0, 3);
		world.setBlock(x + 4, y + 1, z + 7, Blocks.brick_stairs, 2, 3);
		world.setBlock(x + 4, y + 1, z + 6, Blocks.air, 0, 3);
		world.setBlock(x + 4, y + 1, z + 5, Blocks.air, 0, 3);
		world.setBlock(x + 4, y + 1, z + 4, Blocks.air, 0, 3);
		world.setBlock(x + 4, y + 1, z + 3, Blocks.air, 0, 3);
		world.setBlock(x + 4, y + 1, z + 2, Blocks.air, 0, 3);
		world.setBlock(x + 4, y + 1, z + 1, Blocks.planks, 0, 3);
		world.setBlock(x + 4, y + 1, z + 0, Blocks.air, 0, 3);
		world.setBlock(x + 5, y + 1, z + 9, Blocks.air, 0, 3);
		world.setBlock(x + 5, y + 1, z + 8, Blocks.log, 0, 3);
		world.setBlock(x + 5, y + 1, z + 7, Blocks.planks, 0, 3);
		world.setBlock(x + 5, y + 1, z + 6, Blocks.planks, 0, 3);
		world.setBlock(x + 5, y + 1, z + 5, Blocks.planks, 0, 3);
		world.setBlock(x + 5, y + 1, z + 4, Blocks.planks, 0, 3);
		world.setBlock(x + 5, y + 1, z + 2, Blocks.planks, 0, 3);
		world.setBlock(x + 5, y + 1, z + 1, Blocks.log, 0, 3);
		world.setBlock(x + 5, y + 1, z + 0, Blocks.air, 0, 3);
		world.setBlock(x + 6, y + 1, z + 9, Blocks.air, 0, 3);
		world.setBlock(x + 6, y + 1, z + 8, Blocks.air, 0, 3);
		world.setBlock(x + 6, y + 1, z + 7, Blocks.air, 0, 3);
		world.setBlock(x + 6, y + 1, z + 6, Blocks.air, 0, 3);
		world.setBlock(x + 6, y + 1, z + 5, Blocks.air, 0, 3);
		world.setBlock(x + 6, y + 1, z + 4, Blocks.air, 0, 3);
		world.setBlock(x + 6, y + 1, z + 3, Blocks.air, 0, 3);
		world.setBlock(x + 6, y + 1, z + 2, Blocks.air, 0, 3);
		world.setBlock(x + 6, y + 1, z + 1, Blocks.air, 0, 3);
		world.setBlock(x + 6, y + 1, z + 0, Blocks.air, 0, 3);
		world.setBlock(x + 0, y + 2, z + 9, Blocks.air, 0, 3);
		world.setBlock(x + 0, y + 2, z + 8, Blocks.air, 0, 3);
		world.setBlock(x + 0, y + 2, z + 7, Blocks.air, 0, 3);
		world.setBlock(x + 0, y + 2, z + 6, Blocks.air, 0, 3);
		world.setBlock(x + 0, y + 2, z + 5, Blocks.air, 0, 3);
		world.setBlock(x + 0, y + 2, z + 4, Blocks.air, 0, 3);
		world.setBlock(x + 0, y + 2, z + 3, Blocks.air, 0, 3);
		world.setBlock(x + 0, y + 2, z + 2, Blocks.air, 0, 3);
		world.setBlock(x + 0, y + 2, z + 1, Blocks.air, 0, 3);
		world.setBlock(x + 0, y + 2, z + 0, Blocks.air, 0, 3);
		world.setBlock(x + 1, y + 2, z + 9, Blocks.air, 0, 3);
		world.setBlock(x + 1, y + 2, z + 8, Blocks.log, 0, 3);
		world.setBlock(x + 1, y + 2, z + 7, PeatizedBlocks.peat, 1, 3);
		world.setBlock(x + 1, y + 2, z + 6, Blocks.stained_glass_pane, 7, 3);
		world.setBlock(x + 1, y + 2, z + 5, PeatizedBlocks.peat, 1, 3);
		world.setBlock(x + 1, y + 2, z + 4, PeatizedBlocks.peat, 1, 3);
		world.setBlock(x + 1, y + 2, z + 3, Blocks.stained_glass_pane, 7, 3);
		world.setBlock(x + 1, y + 2, z + 2, PeatizedBlocks.peat, 1, 3);
		world.setBlock(x + 1, y + 2, z + 1, Blocks.log, 0, 3);
		world.setBlock(x + 1, y + 2, z + 0, Blocks.air, 0, 3);
		world.setBlock(x + 2, y + 2, z + 9, Blocks.air, 0, 3);
		world.setBlock(x + 2, y + 2, z + 8, PeatizedBlocks.peat, 0, 3);
		world.setBlock(x + 2, y + 2, z + 7, Blocks.air, 0, 3);
		world.setBlock(x + 2, y + 2, z + 6, Blocks.air, 0, 3);
		world.setBlock(x + 2, y + 2, z + 5, Blocks.air, 0, 3);
		world.setBlock(x + 2, y + 2, z + 4, Blocks.air, 0, 3);
		world.setBlock(x + 2, y + 2, z + 3, Blocks.air, 0, 3);
		world.setBlock(x + 2, y + 2, z + 2, Blocks.air, 0, 3);
		world.setBlock(x + 2, y + 2, z + 1, PeatizedBlocks.peat, 1, 3);
		world.setBlock(x + 2, y + 2, z + 0, Blocks.air, 0, 3);
		world.setBlock(x + 3, y + 2, z + 9, Blocks.brick_stairs, 3, 3);
		world.setBlock(x + 3, y + 2, z + 8, Blocks.brick_block, 0, 3);
		world.setBlock(x + 3, y + 2, z + 7, Blocks.air, 0, 3);
		world.setBlock(x + 3, y + 2, z + 6, Blocks.air, 0, 3);
		world.setBlock(x + 3, y + 2, z + 5, Blocks.air, 0, 3);
		world.setBlock(x + 3, y + 2, z + 4, Blocks.air, 0, 3);
		world.setBlock(x + 3, y + 2, z + 3, Blocks.air, 0, 3);
		world.setBlock(x + 3, y + 2, z + 2, Blocks.air, 0, 3);
		world.setBlock(x + 3, y + 2, z + 1, Blocks.stained_glass_pane, 7, 3);
		world.setBlock(x + 3, y + 2, z + 0, Blocks.air, 0, 3);
		world.setBlock(x + 4, y + 2, z + 9, Blocks.air, 0, 3);
		world.setBlock(x + 4, y + 2, z + 8, PeatizedBlocks.peat, 0, 3);
		world.setBlock(x + 4, y + 2, z + 7, Blocks.air, 0, 3);
		world.setBlock(x + 4, y + 2, z + 6, Blocks.air, 0, 3);
		world.setBlock(x + 4, y + 2, z + 5, Blocks.air, 0, 3);
		world.setBlock(x + 4, y + 2, z + 3, Blocks.air, 0, 3);
		world.setBlock(x + 4, y + 2, z + 2, Blocks.air, 0, 3);
		world.setBlock(x + 4, y + 2, z + 1, PeatizedBlocks.peat, 1, 3);
		world.setBlock(x + 4, y + 2, z + 0, Blocks.air, 0, 3);
		world.setBlock(x + 5, y + 2, z + 9, Blocks.air, 0, 3);
		world.setBlock(x + 5, y + 2, z + 8, Blocks.log, 0, 3);
		world.setBlock(x + 5, y + 2, z + 7, PeatizedBlocks.peat, 1, 3);
		world.setBlock(x + 5, y + 2, z + 6, Blocks.stained_glass_pane, 7, 3);
		world.setBlock(x + 5, y + 2, z + 5, Blocks.stained_glass_pane, 7, 3);
		world.setBlock(x + 5, y + 2, z + 4, PeatizedBlocks.peat, 1, 3);
		world.setBlock(x + 5, y + 2, z + 2, PeatizedBlocks.peat, 1, 3);
		world.setBlock(x + 5, y + 2, z + 1, Blocks.log, 0, 3);
		world.setBlock(x + 5, y + 2, z + 0, Blocks.air, 0, 3);
		world.setBlock(x + 6, y + 2, z + 9, Blocks.air, 0, 3);
		world.setBlock(x + 6, y + 2, z + 8, Blocks.air, 0, 3);
		world.setBlock(x + 6, y + 2, z + 7, Blocks.air, 0, 3);
		world.setBlock(x + 6, y + 2, z + 6, Blocks.air, 0, 3);
		world.setBlock(x + 6, y + 2, z + 5, Blocks.air, 0, 3);
		world.setBlock(x + 6, y + 2, z + 3, Blocks.air, 0, 3);
		world.setBlock(x + 6, y + 2, z + 2, Blocks.air, 0, 3);
		world.setBlock(x + 6, y + 2, z + 1, Blocks.air, 0, 3);
		world.setBlock(x + 6, y + 2, z + 0, Blocks.air, 0, 3);
		world.setBlock(x + 0, y + 3, z + 9, PeatizedBlocks.peatStairs, 0, 3);
		world.setBlock(x + 0, y + 3, z + 8, PeatizedBlocks.peatStairs, 0, 3);
		world.setBlock(x + 0, y + 3, z + 7, PeatizedBlocks.peatStairs, 0, 3);
		world.setBlock(x + 0, y + 3, z + 6, PeatizedBlocks.peatStairs, 0, 3);
		world.setBlock(x + 0, y + 3, z + 5, PeatizedBlocks.peatStairs, 0, 3);
		world.setBlock(x + 0, y + 3, z + 4, PeatizedBlocks.peatStairs, 0, 3);
		world.setBlock(x + 0, y + 3, z + 3, PeatizedBlocks.peatStairs, 0, 3);
		world.setBlock(x + 0, y + 3, z + 2, PeatizedBlocks.peatStairs, 0, 3);
		world.setBlock(x + 0, y + 3, z + 1, PeatizedBlocks.peatStairs, 0, 3);
		world.setBlock(x + 0, y + 3, z + 0, PeatizedBlocks.peatStairs, 0, 3);
		world.setBlock(x + 1, y + 3, z + 9, PeatizedBlocks.peatStairs, 5, 3);
		world.setBlock(x + 1, y + 3, z + 8, Blocks.log, 0, 3);
		world.setBlock(x + 1, y + 3, z + 7, Blocks.planks, 0, 3);
		world.setBlock(x + 1, y + 3, z + 6, Blocks.planks, 0, 3);
		world.setBlock(x + 1, y + 3, z + 5, Blocks.planks, 0, 3);
		world.setBlock(x + 1, y + 3, z + 4, Blocks.planks, 0, 3);
		world.setBlock(x + 1, y + 3, z + 3, Blocks.planks, 0, 3);
		world.setBlock(x + 1, y + 3, z + 2, Blocks.planks, 0, 3);
		world.setBlock(x + 1, y + 3, z + 1, Blocks.log, 0, 3);
		world.setBlock(x + 1, y + 3, z + 0, PeatizedBlocks.peatStairs, 5, 3);
		world.setBlock(x + 2, y + 3, z + 9, Blocks.air, 0, 3);
		world.setBlock(x + 2, y + 3, z + 8, PeatizedBlocks.peat, 0, 3);
		world.setBlock(x + 2, y + 3, z + 7, Blocks.air, 0, 3);
		world.setBlock(x + 2, y + 3, z + 6, Blocks.air, 0, 3);
		world.setBlock(x + 2, y + 3, z + 5, Blocks.air, 0, 3);
		world.setBlock(x + 2, y + 3, z + 4, Blocks.air, 0, 3);
		world.setBlock(x + 2, y + 3, z + 3, Blocks.air, 0, 3);
		world.setBlock(x + 2, y + 3, z + 2, Blocks.air, 0, 3);
		world.setBlock(x + 2, y + 3, z + 1, Blocks.planks, 0, 3);
		world.setBlock(x + 2, y + 3, z + 0, Blocks.air, 0, 3);
		world.setBlock(x + 3, y + 3, z + 9, Blocks.air, 0, 3);
		world.setBlock(x + 3, y + 3, z + 8, Blocks.brick_block, 0, 3);
		world.setBlock(x + 3, y + 3, z + 7, Blocks.air, 0, 3);
		world.setBlock(x + 3, y + 3, z + 6, Blocks.air, 0, 3);
		world.setBlock(x + 3, y + 3, z + 5, Blocks.air, 0, 3);
		world.setBlock(x + 3, y + 3, z + 4, Blocks.air, 0, 3);
		world.setBlock(x + 3, y + 3, z + 3, Blocks.air, 0, 3);
		world.setBlock(x + 3, y + 3, z + 2, Blocks.air, 0, 3);
		world.setBlock(x + 3, y + 3, z + 1, Blocks.planks, 0, 3);
		world.setBlock(x + 3, y + 3, z + 0, Blocks.air, 0, 3);
		world.setBlock(x + 4, y + 3, z + 9, Blocks.air, 0, 3);
		world.setBlock(x + 4, y + 3, z + 8, PeatizedBlocks.peat, 0, 3);
		world.setBlock(x + 4, y + 3, z + 7, Blocks.air, 0, 3);
		world.setBlock(x + 4, y + 3, z + 6, Blocks.air, 0, 3);
		world.setBlock(x + 4, y + 3, z + 5, Blocks.air, 0, 3);
		world.setBlock(x + 4, y + 3, z + 4, Blocks.air, 0, 3);
		world.setBlock(x + 4, y + 3, z + 3, Blocks.air, 0, 3);
		world.setBlock(x + 4, y + 3, z + 2, Blocks.air, 0, 3);
		world.setBlock(x + 4, y + 3, z + 1, Blocks.planks, 0, 3);
		world.setBlock(x + 4, y + 3, z + 0, Blocks.air, 0, 3);
		world.setBlock(x + 5, y + 3, z + 9, PeatizedBlocks.peatStairs, 4, 3);
		world.setBlock(x + 5, y + 3, z + 8, Blocks.log, 0, 3);
		world.setBlock(x + 5, y + 3, z + 7, Blocks.planks, 0, 3);
		world.setBlock(x + 5, y + 3, z + 6, Blocks.planks, 0, 3);
		world.setBlock(x + 5, y + 3, z + 5, Blocks.planks, 0, 3);
		world.setBlock(x + 5, y + 3, z + 4, Blocks.planks, 0, 3);
		world.setBlock(x + 5, y + 3, z + 3, Blocks.planks, 0, 3);
		world.setBlock(x + 5, y + 3, z + 2, Blocks.planks, 0, 3);
		world.setBlock(x + 5, y + 3, z + 1, Blocks.log, 0, 3);
		world.setBlock(x + 5, y + 3, z + 0, PeatizedBlocks.peatStairs, 4, 3);
		world.setBlock(x + 6, y + 3, z + 9, PeatizedBlocks.peatStairs, 1, 3);
		world.setBlock(x + 6, y + 3, z + 8, PeatizedBlocks.peatStairs, 1, 3);
		world.setBlock(x + 6, y + 3, z + 7, PeatizedBlocks.peatStairs, 1, 3);
		world.setBlock(x + 6, y + 3, z + 6, PeatizedBlocks.peatStairs, 1, 3);
		world.setBlock(x + 6, y + 3, z + 5, PeatizedBlocks.peatStairs, 1, 3);
		world.setBlock(x + 6, y + 3, z + 4, PeatizedBlocks.peatStairs, 1, 3);
		world.setBlock(x + 6, y + 3, z + 3, PeatizedBlocks.peatStairs, 1, 3);
		world.setBlock(x + 6, y + 3, z + 2, PeatizedBlocks.peatStairs, 1, 3);
		world.setBlock(x + 6, y + 3, z + 1, PeatizedBlocks.peatStairs, 1, 3);
		world.setBlock(x + 6, y + 3, z + 0, PeatizedBlocks.peatStairs, 1, 3);
		world.setBlock(x + 0, y + 4, z + 9, Blocks.air, 0, 3);
		world.setBlock(x + 0, y + 4, z + 8, Blocks.air, 0, 3);
		world.setBlock(x + 0, y + 4, z + 7, Blocks.air, 0, 3);
		world.setBlock(x + 0, y + 4, z + 6, Blocks.air, 0, 3);
		world.setBlock(x + 0, y + 4, z + 5, Blocks.air, 0, 3);
		world.setBlock(x + 0, y + 4, z + 4, Blocks.air, 0, 3);
		world.setBlock(x + 0, y + 4, z + 3, Blocks.air, 0, 3);
		world.setBlock(x + 0, y + 4, z + 2, Blocks.air, 0, 3);
		world.setBlock(x + 0, y + 4, z + 1, Blocks.air, 0, 3);
		world.setBlock(x + 0, y + 4, z + 0, Blocks.air, 0, 3);
		world.setBlock(x + 1, y + 4, z + 9, PeatizedBlocks.peatStairs, 0, 3);
		world.setBlock(x + 1, y + 4, z + 8, PeatizedBlocks.peatStairs, 0, 3);
		world.setBlock(x + 1, y + 4, z + 7, PeatizedBlocks.peatStairs, 0, 3);
		world.setBlock(x + 1, y + 4, z + 6, PeatizedBlocks.peatStairs, 0, 3);
		world.setBlock(x + 1, y + 4, z + 5, PeatizedBlocks.peatStairs, 0, 3);
		world.setBlock(x + 1, y + 4, z + 4, PeatizedBlocks.peatStairs, 0, 3);
		world.setBlock(x + 1, y + 4, z + 3, PeatizedBlocks.peatStairs, 0, 3);
		world.setBlock(x + 1, y + 4, z + 2, PeatizedBlocks.peatStairs, 0, 3);
		world.setBlock(x + 1, y + 4, z + 1, PeatizedBlocks.peatStairs, 0, 3);
		world.setBlock(x + 1, y + 4, z + 0, PeatizedBlocks.peatStairs, 0, 3);
		world.setBlock(x + 2, y + 4, z + 9, PeatizedBlocks.peatStairs, 5, 3);
		world.setBlock(x + 2, y + 4, z + 8, PeatizedBlocks.peat, 0, 3);
		world.setBlock(x + 2, y + 4, z + 7, Blocks.wooden_slab, 8, 3);
		world.setBlock(x + 2, y + 4, z + 6, Blocks.log, 4, 3);
		world.setBlock(x + 2, y + 4, z + 5, Blocks.wooden_slab, 8, 3);
		world.setBlock(x + 2, y + 4, z + 4, Blocks.wooden_slab, 8, 3);
		world.setBlock(x + 2, y + 4, z + 3, Blocks.log, 4, 3);
		world.setBlock(x + 2, y + 4, z + 2, Blocks.wooden_slab, 8, 3);
		world.setBlock(x + 2, y + 4, z + 1, PeatizedBlocks.peat, 0, 3);
		world.setBlock(x + 2, y + 4, z + 0, PeatizedBlocks.peatStairs, 5, 3);
		world.setBlock(x + 3, y + 4, z + 9, Blocks.air, 0, 3);
		world.setBlock(x + 3, y + 4, z + 8, Blocks.brick_block, 0, 3);
		world.setBlock(x + 3, y + 4, z + 7, Blocks.log, 8, 3);
		world.setBlock(x + 3, y + 4, z + 6, Blocks.log, 8, 3);
		world.setBlock(x + 3, y + 4, z + 5, Blocks.log, 8, 3);
		world.setBlock(x + 3, y + 4, z + 4, Blocks.log, 8, 3);
		world.setBlock(x + 3, y + 4, z + 3, Blocks.log, 8, 3);
		world.setBlock(x + 3, y + 4, z + 2, Blocks.log, 8, 3);
		world.setBlock(x + 3, y + 4, z + 1, PeatizedBlocks.peat, 0, 3);
		world.setBlock(x + 3, y + 4, z + 0, Blocks.air, 0, 3);
		world.setBlock(x + 4, y + 4, z + 9, PeatizedBlocks.peatStairs, 4, 3);
		world.setBlock(x + 4, y + 4, z + 8, PeatizedBlocks.peat, 0, 3);
		world.setBlock(x + 4, y + 4, z + 7, Blocks.wooden_slab, 8, 3);
		world.setBlock(x + 4, y + 4, z + 6, Blocks.log, 4, 3);
		world.setBlock(x + 4, y + 4, z + 5, Blocks.wooden_slab, 8, 3);
		world.setBlock(x + 4, y + 4, z + 4, Blocks.wooden_slab, 8, 3);
		world.setBlock(x + 4, y + 4, z + 3, Blocks.log, 4, 3);
		world.setBlock(x + 4, y + 4, z + 2, Blocks.wooden_slab, 8, 3);
		world.setBlock(x + 4, y + 4, z + 1, PeatizedBlocks.peat, 0, 3);
		world.setBlock(x + 4, y + 4, z + 0, PeatizedBlocks.peatStairs, 4, 3);
		world.setBlock(x + 5, y + 4, z + 9, PeatizedBlocks.peatStairs, 1, 3);
		world.setBlock(x + 5, y + 4, z + 8, PeatizedBlocks.peatStairs, 1, 3);
		world.setBlock(x + 5, y + 4, z + 7, PeatizedBlocks.peatStairs, 1, 3);
		world.setBlock(x + 5, y + 4, z + 6, PeatizedBlocks.peatStairs, 1, 3);
		world.setBlock(x + 5, y + 4, z + 5, PeatizedBlocks.peatStairs, 1, 3);
		world.setBlock(x + 5, y + 4, z + 4, PeatizedBlocks.peatStairs, 1, 3);
		world.setBlock(x + 5, y + 4, z + 3, PeatizedBlocks.peatStairs, 1, 3);
		world.setBlock(x + 5, y + 4, z + 2, PeatizedBlocks.peatStairs, 1, 3);
		world.setBlock(x + 5, y + 4, z + 1, PeatizedBlocks.peatStairs, 1, 3);
		world.setBlock(x + 5, y + 4, z + 0, PeatizedBlocks.peatStairs, 1, 3);
		world.setBlock(x + 6, y + 4, z + 9, Blocks.air, 0, 3);
		world.setBlock(x + 6, y + 4, z + 8, Blocks.air, 0, 3);
		world.setBlock(x + 6, y + 4, z + 7, Blocks.air, 0, 3);
		world.setBlock(x + 6, y + 4, z + 6, Blocks.air, 0, 3);
		world.setBlock(x + 6, y + 4, z + 5, Blocks.air, 0, 3);
		world.setBlock(x + 6, y + 4, z + 4, Blocks.air, 0, 3);
		world.setBlock(x + 6, y + 4, z + 3, Blocks.air, 0, 3);
		world.setBlock(x + 6, y + 4, z + 2, Blocks.air, 0, 3);
		world.setBlock(x + 6, y + 4, z + 1, Blocks.air, 0, 3);
		world.setBlock(x + 6, y + 4, z + 0, Blocks.air, 0, 3);
		world.setBlock(x + 0, y + 5, z + 9, Blocks.air, 0, 3);
		world.setBlock(x + 0, y + 5, z + 8, Blocks.air, 0, 3);
		world.setBlock(x + 0, y + 5, z + 7, Blocks.air, 0, 3);
		world.setBlock(x + 0, y + 5, z + 6, Blocks.air, 0, 3);
		world.setBlock(x + 0, y + 5, z + 5, Blocks.air, 0, 3);
		world.setBlock(x + 0, y + 5, z + 4, Blocks.air, 0, 3);
		world.setBlock(x + 0, y + 5, z + 3, Blocks.air, 0, 3);
		world.setBlock(x + 0, y + 5, z + 2, Blocks.air, 0, 3);
		world.setBlock(x + 0, y + 5, z + 1, Blocks.air, 0, 3);
		world.setBlock(x + 0, y + 5, z + 0, Blocks.air, 0, 3);
		world.setBlock(x + 1, y + 5, z + 9, Blocks.air, 0, 3);
		world.setBlock(x + 1, y + 5, z + 8, Blocks.air, 0, 3);
		world.setBlock(x + 1, y + 5, z + 7, Blocks.air, 0, 3);
		world.setBlock(x + 1, y + 5, z + 6, Blocks.air, 0, 3);
		world.setBlock(x + 1, y + 5, z + 5, Blocks.air, 0, 3);
		world.setBlock(x + 1, y + 5, z + 4, Blocks.air, 0, 3);
		world.setBlock(x + 1, y + 5, z + 3, Blocks.air, 0, 3);
		world.setBlock(x + 1, y + 5, z + 2, Blocks.air, 0, 3);
		world.setBlock(x + 1, y + 5, z + 1, Blocks.air, 0, 3);
		world.setBlock(x + 1, y + 5, z + 0, Blocks.air, 0, 3);
		world.setBlock(x + 2, y + 5, z + 9, PeatizedBlocks.peatStairs, 0, 3);
		world.setBlock(x + 2, y + 5, z + 8, PeatizedBlocks.peatStairs, 0, 3);
		world.setBlock(x + 2, y + 5, z + 7, PeatizedBlocks.peatStairs, 0, 3);
		world.setBlock(x + 2, y + 5, z + 6, PeatizedBlocks.peatStairs, 0, 3);
		world.setBlock(x + 2, y + 5, z + 5, PeatizedBlocks.peatStairs, 0, 3);
		world.setBlock(x + 2, y + 5, z + 4, PeatizedBlocks.peatStairs, 0, 3);
		world.setBlock(x + 2, y + 5, z + 3, PeatizedBlocks.peatStairs, 0, 3);
		world.setBlock(x + 2, y + 5, z + 2, PeatizedBlocks.peatStairs, 0, 3);
		world.setBlock(x + 2, y + 5, z + 1, PeatizedBlocks.peatStairs, 0, 3);
		world.setBlock(x + 2, y + 5, z + 0, PeatizedBlocks.peatStairs, 0, 3);
		world.setBlock(x + 3, y + 5, z + 9, PeatizedBlocks.peat, 0, 3);
		world.setBlock(x + 3, y + 5, z + 8, Blocks.brick_block, 0, 3);
		world.setBlock(x + 3, y + 5, z + 7, PeatizedBlocks.peat, 0, 3);
		world.setBlock(x + 3, y + 5, z + 6, PeatizedBlocks.peat, 0, 3);
		world.setBlock(x + 3, y + 5, z + 5, PeatizedBlocks.peat, 0, 3);
		world.setBlock(x + 3, y + 5, z + 4, PeatizedBlocks.peat, 0, 3);
		world.setBlock(x + 3, y + 5, z + 3, PeatizedBlocks.peat, 0, 3);
		world.setBlock(x + 3, y + 5, z + 2, PeatizedBlocks.peat, 0, 3);
		world.setBlock(x + 3, y + 5, z + 1, PeatizedBlocks.peat, 0, 3);
		world.setBlock(x + 3, y + 5, z + 0, PeatizedBlocks.peat, 0, 3);
		world.setBlock(x + 4, y + 5, z + 9, PeatizedBlocks.peatStairs, 1, 3);
		world.setBlock(x + 4, y + 5, z + 8, PeatizedBlocks.peatStairs, 1, 3);
		world.setBlock(x + 4, y + 5, z + 7, PeatizedBlocks.peatStairs, 1, 3);
		world.setBlock(x + 4, y + 5, z + 6, PeatizedBlocks.peatStairs, 1, 3);
		world.setBlock(x + 4, y + 5, z + 5, PeatizedBlocks.peatStairs, 1, 3);
		world.setBlock(x + 4, y + 5, z + 4, PeatizedBlocks.peatStairs, 1, 3);
		world.setBlock(x + 4, y + 5, z + 3, PeatizedBlocks.peatStairs, 1, 3);
		world.setBlock(x + 4, y + 5, z + 2, PeatizedBlocks.peatStairs, 1, 3);
		world.setBlock(x + 4, y + 5, z + 1, PeatizedBlocks.peatStairs, 1, 3);
		world.setBlock(x + 4, y + 5, z + 0, PeatizedBlocks.peatStairs, 1, 3);
		world.setBlock(x + 5, y + 5, z + 9, Blocks.air, 0, 3);
		world.setBlock(x + 5, y + 5, z + 8, Blocks.air, 0, 3);
		world.setBlock(x + 5, y + 5, z + 7, Blocks.air, 0, 3);
		world.setBlock(x + 5, y + 5, z + 6, Blocks.air, 0, 3);
		world.setBlock(x + 5, y + 5, z + 5, Blocks.air, 0, 3);
		world.setBlock(x + 5, y + 5, z + 4, Blocks.air, 0, 3);
		world.setBlock(x + 5, y + 5, z + 3, Blocks.air, 0, 3);
		world.setBlock(x + 5, y + 5, z + 2, Blocks.air, 0, 3);
		world.setBlock(x + 5, y + 5, z + 1, Blocks.air, 0, 3);
		world.setBlock(x + 5, y + 5, z + 0, Blocks.air, 0, 3);
		world.setBlock(x + 6, y + 5, z + 9, Blocks.air, 0, 3);
		world.setBlock(x + 6, y + 5, z + 8, Blocks.air, 0, 3);
		world.setBlock(x + 6, y + 5, z + 7, Blocks.air, 0, 3);
		world.setBlock(x + 6, y + 5, z + 6, Blocks.air, 0, 3);
		world.setBlock(x + 6, y + 5, z + 5, Blocks.air, 0, 3);
		world.setBlock(x + 6, y + 5, z + 4, Blocks.air, 0, 3);
		world.setBlock(x + 6, y + 5, z + 3, Blocks.air, 0, 3);
		world.setBlock(x + 6, y + 5, z + 2, Blocks.air, 0, 3);
		world.setBlock(x + 6, y + 5, z + 1, Blocks.air, 0, 3);
		world.setBlock(x + 6, y + 5, z + 0, Blocks.air, 0, 3);
		world.setBlock(x + 0, y + 6, z + 9, Blocks.air, 0, 3);
		world.setBlock(x + 0, y + 6, z + 8, Blocks.air, 0, 3);
		world.setBlock(x + 0, y + 6, z + 7, Blocks.air, 0, 3);
		world.setBlock(x + 0, y + 6, z + 6, Blocks.air, 0, 3);
		world.setBlock(x + 0, y + 6, z + 5, Blocks.air, 0, 3);
		world.setBlock(x + 0, y + 6, z + 4, Blocks.air, 0, 3);
		world.setBlock(x + 0, y + 6, z + 3, Blocks.air, 0, 3);
		world.setBlock(x + 0, y + 6, z + 2, Blocks.air, 0, 3);
		world.setBlock(x + 0, y + 6, z + 1, Blocks.air, 0, 3);
		world.setBlock(x + 0, y + 6, z + 0, Blocks.air, 0, 3);
		world.setBlock(x + 1, y + 6, z + 9, Blocks.air, 0, 3);
		world.setBlock(x + 1, y + 6, z + 8, Blocks.air, 0, 3);
		world.setBlock(x + 1, y + 6, z + 7, Blocks.air, 0, 3);
		world.setBlock(x + 1, y + 6, z + 6, Blocks.air, 0, 3);
		world.setBlock(x + 1, y + 6, z + 5, Blocks.air, 0, 3);
		world.setBlock(x + 1, y + 6, z + 4, Blocks.air, 0, 3);
		world.setBlock(x + 1, y + 6, z + 3, Blocks.air, 0, 3);
		world.setBlock(x + 1, y + 6, z + 2, Blocks.air, 0, 3);
		world.setBlock(x + 1, y + 6, z + 1, Blocks.air, 0, 3);
		world.setBlock(x + 1, y + 6, z + 0, Blocks.air, 0, 3);
		world.setBlock(x + 2, y + 6, z + 9, Blocks.air, 0, 3);
		world.setBlock(x + 2, y + 6, z + 8, Blocks.air, 0, 3);
		world.setBlock(x + 2, y + 6, z + 7, Blocks.air, 0, 3);
		world.setBlock(x + 2, y + 6, z + 6, Blocks.air, 0, 3);
		world.setBlock(x + 2, y + 6, z + 5, Blocks.air, 0, 3);
		world.setBlock(x + 2, y + 6, z + 4, Blocks.air, 0, 3);
		world.setBlock(x + 2, y + 6, z + 3, Blocks.air, 0, 3);
		world.setBlock(x + 2, y + 6, z + 2, Blocks.air, 0, 3);
		world.setBlock(x + 2, y + 6, z + 1, Blocks.air, 0, 3);
		world.setBlock(x + 2, y + 6, z + 0, Blocks.air, 0, 3);
		world.setBlock(x + 3, y + 6, z + 9, PeatizedBlocks.peatSlab, 0, 3);
		world.setBlock(x + 3, y + 6, z + 8, Blocks.brick_block, 0, 3);
		world.setBlock(x + 3, y + 6, z + 7, PeatizedBlocks.peatSlab, 0, 3);
		world.setBlock(x + 3, y + 6, z + 6, PeatizedBlocks.peatSlab, 0, 3);
		world.setBlock(x + 3, y + 6, z + 5, PeatizedBlocks.peatSlab, 0, 3);
		world.setBlock(x + 3, y + 6, z + 4, PeatizedBlocks.peatSlab, 0, 3);
		world.setBlock(x + 3, y + 6, z + 3, PeatizedBlocks.peatSlab, 0, 3);
		world.setBlock(x + 3, y + 6, z + 2, PeatizedBlocks.peatSlab, 0, 3);
		world.setBlock(x + 3, y + 6, z + 1, PeatizedBlocks.peatSlab, 0, 3);
		world.setBlock(x + 3, y + 6, z + 0, PeatizedBlocks.peatSlab, 0, 3);
		world.setBlock(x + 4, y + 6, z + 9, Blocks.air, 0, 3);
		world.setBlock(x + 4, y + 6, z + 8, Blocks.air, 0, 3);
		world.setBlock(x + 4, y + 6, z + 7, Blocks.air, 0, 3);
		world.setBlock(x + 4, y + 6, z + 6, Blocks.air, 0, 3);
		world.setBlock(x + 4, y + 6, z + 5, Blocks.air, 0, 3);
		world.setBlock(x + 4, y + 6, z + 4, Blocks.air, 0, 3);
		world.setBlock(x + 4, y + 6, z + 3, Blocks.air, 0, 3);
		world.setBlock(x + 4, y + 6, z + 2, Blocks.air, 0, 3);
		world.setBlock(x + 4, y + 6, z + 1, Blocks.air, 0, 3);
		world.setBlock(x + 4, y + 6, z + 0, Blocks.air, 0, 3);
		world.setBlock(x + 5, y + 6, z + 9, Blocks.air, 0, 3);
		world.setBlock(x + 5, y + 6, z + 8, Blocks.air, 0, 3);
		world.setBlock(x + 5, y + 6, z + 7, Blocks.air, 0, 3);
		world.setBlock(x + 5, y + 6, z + 6, Blocks.air, 0, 3);
		world.setBlock(x + 5, y + 6, z + 5, Blocks.air, 0, 3);
		world.setBlock(x + 5, y + 6, z + 4, Blocks.air, 0, 3);
		world.setBlock(x + 5, y + 6, z + 3, Blocks.air, 0, 3);
		world.setBlock(x + 5, y + 6, z + 2, Blocks.air, 0, 3);
		world.setBlock(x + 5, y + 6, z + 1, Blocks.air, 0, 3);
		world.setBlock(x + 5, y + 6, z + 0, Blocks.air, 0, 3);
		world.setBlock(x + 6, y + 6, z + 9, Blocks.air, 0, 3);
		world.setBlock(x + 6, y + 6, z + 8, Blocks.air, 0, 3);
		world.setBlock(x + 6, y + 6, z + 7, Blocks.air, 0, 3);
		world.setBlock(x + 6, y + 6, z + 6, Blocks.air, 0, 3);
		world.setBlock(x + 6, y + 6, z + 5, Blocks.air, 0, 3);
		world.setBlock(x + 6, y + 6, z + 4, Blocks.air, 0, 3);
		world.setBlock(x + 6, y + 6, z + 3, Blocks.air, 0, 3);
		world.setBlock(x + 6, y + 6, z + 2, Blocks.air, 0, 3);
		world.setBlock(x + 6, y + 6, z + 1, Blocks.air, 0, 3);
		world.setBlock(x + 6, y + 6, z + 0, Blocks.air, 0, 3);
		world.setBlock(x + 0, y + 7, z + 9, Blocks.air, 0, 3);
		world.setBlock(x + 0, y + 7, z + 8, Blocks.air, 0, 3);
		world.setBlock(x + 0, y + 7, z + 7, Blocks.air, 0, 3);
		world.setBlock(x + 0, y + 7, z + 6, Blocks.air, 0, 3);
		world.setBlock(x + 0, y + 7, z + 5, Blocks.air, 0, 3);
		world.setBlock(x + 0, y + 7, z + 4, Blocks.air, 0, 3);
		world.setBlock(x + 0, y + 7, z + 3, Blocks.air, 0, 3);
		world.setBlock(x + 0, y + 7, z + 2, Blocks.air, 0, 3);
		world.setBlock(x + 0, y + 7, z + 1, Blocks.air, 0, 3);
		world.setBlock(x + 0, y + 7, z + 0, Blocks.air, 0, 3);
		world.setBlock(x + 1, y + 7, z + 9, Blocks.air, 0, 3);
		world.setBlock(x + 1, y + 7, z + 8, Blocks.air, 0, 3);
		world.setBlock(x + 1, y + 7, z + 7, Blocks.air, 0, 3);
		world.setBlock(x + 1, y + 7, z + 6, Blocks.air, 0, 3);
		world.setBlock(x + 1, y + 7, z + 5, Blocks.air, 0, 3);
		world.setBlock(x + 1, y + 7, z + 4, Blocks.air, 0, 3);
		world.setBlock(x + 1, y + 7, z + 3, Blocks.air, 0, 3);
		world.setBlock(x + 1, y + 7, z + 2, Blocks.air, 0, 3);
		world.setBlock(x + 1, y + 7, z + 1, Blocks.air, 0, 3);
		world.setBlock(x + 1, y + 7, z + 0, Blocks.air, 0, 3);
		world.setBlock(x + 2, y + 7, z + 9, Blocks.air, 0, 3);
		world.setBlock(x + 2, y + 7, z + 8, Blocks.air, 0, 3);
		world.setBlock(x + 2, y + 7, z + 7, Blocks.air, 0, 3);
		world.setBlock(x + 2, y + 7, z + 6, Blocks.air, 0, 3);
		world.setBlock(x + 2, y + 7, z + 5, Blocks.air, 0, 3);
		world.setBlock(x + 2, y + 7, z + 4, Blocks.air, 0, 3);
		world.setBlock(x + 2, y + 7, z + 3, Blocks.air, 0, 3);
		world.setBlock(x + 2, y + 7, z + 2, Blocks.air, 0, 3);
		world.setBlock(x + 2, y + 7, z + 1, Blocks.air, 0, 3);
		world.setBlock(x + 2, y + 7, z + 0, Blocks.air, 0, 3);
		world.setBlock(x + 3, y + 7, z + 9, Blocks.air, 0, 3);
		world.setBlock(x + 3, y + 7, z + 8, Blocks.cobblestone_wall, 0, 3);
		world.setBlock(x + 3, y + 7, z + 7, Blocks.air, 0, 3);
		world.setBlock(x + 3, y + 7, z + 6, Blocks.air, 0, 3);
		world.setBlock(x + 3, y + 7, z + 5, Blocks.air, 0, 3);
		world.setBlock(x + 3, y + 7, z + 4, Blocks.air, 0, 3);
		world.setBlock(x + 3, y + 7, z + 3, Blocks.air, 0, 3);
		world.setBlock(x + 3, y + 7, z + 2, Blocks.air, 0, 3);
		world.setBlock(x + 3, y + 7, z + 1, Blocks.air, 0, 3);
		world.setBlock(x + 3, y + 7, z + 0, Blocks.air, 0, 3);
		world.setBlock(x + 4, y + 7, z + 9, Blocks.air, 0, 3);
		world.setBlock(x + 4, y + 7, z + 8, Blocks.air, 0, 3);
		world.setBlock(x + 4, y + 7, z + 7, Blocks.air, 0, 3);
		world.setBlock(x + 4, y + 7, z + 6, Blocks.air, 0, 3);
		world.setBlock(x + 4, y + 7, z + 5, Blocks.air, 0, 3);
		world.setBlock(x + 4, y + 7, z + 4, Blocks.air, 0, 3);
		world.setBlock(x + 4, y + 7, z + 3, Blocks.air, 0, 3);
		world.setBlock(x + 4, y + 7, z + 2, Blocks.air, 0, 3);
		world.setBlock(x + 4, y + 7, z + 1, Blocks.air, 0, 3);
		world.setBlock(x + 4, y + 7, z + 0, Blocks.air, 0, 3);
		world.setBlock(x + 5, y + 7, z + 9, Blocks.air, 0, 3);
		world.setBlock(x + 5, y + 7, z + 8, Blocks.air, 0, 3);
		world.setBlock(x + 5, y + 7, z + 7, Blocks.air, 0, 3);
		world.setBlock(x + 5, y + 7, z + 6, Blocks.air, 0, 3);
		world.setBlock(x + 5, y + 7, z + 5, Blocks.air, 0, 3);
		world.setBlock(x + 5, y + 7, z + 4, Blocks.air, 0, 3);
		world.setBlock(x + 5, y + 7, z + 3, Blocks.air, 0, 3);
		world.setBlock(x + 5, y + 7, z + 2, Blocks.air, 0, 3);
		world.setBlock(x + 5, y + 7, z + 1, Blocks.air, 0, 3);
		world.setBlock(x + 5, y + 7, z + 0, Blocks.air, 0, 3);
		world.setBlock(x + 6, y + 7, z + 9, Blocks.air, 0, 3);
		world.setBlock(x + 6, y + 7, z + 8, Blocks.air, 0, 3);
		world.setBlock(x + 6, y + 7, z + 7, Blocks.air, 0, 3);
		world.setBlock(x + 6, y + 7, z + 6, Blocks.air, 0, 3);
		world.setBlock(x + 6, y + 7, z + 5, Blocks.air, 0, 3);
		world.setBlock(x + 6, y + 7, z + 4, Blocks.air, 0, 3);
		world.setBlock(x + 6, y + 7, z + 3, Blocks.air, 0, 3);
		world.setBlock(x + 6, y + 7, z + 2, Blocks.air, 0, 3);
		world.setBlock(x + 6, y + 7, z + 1, Blocks.air, 0, 3);
		world.setBlock(x + 6, y + 7, z + 0, Blocks.air, 0, 3);
		world.setBlock(x + 0, y + 8, z + 9, Blocks.air, 0, 3);
		world.setBlock(x + 0, y + 8, z + 8, Blocks.air, 0, 3);
		world.setBlock(x + 0, y + 8, z + 7, Blocks.air, 0, 3);
		world.setBlock(x + 0, y + 8, z + 6, Blocks.air, 0, 3);
		world.setBlock(x + 0, y + 8, z + 5, Blocks.air, 0, 3);
		world.setBlock(x + 0, y + 8, z + 4, Blocks.air, 0, 3);
		world.setBlock(x + 0, y + 8, z + 3, Blocks.air, 0, 3);
		world.setBlock(x + 0, y + 8, z + 2, Blocks.air, 0, 3);
		world.setBlock(x + 0, y + 8, z + 1, Blocks.air, 0, 3);
		world.setBlock(x + 0, y + 8, z + 0, Blocks.air, 0, 3);
		world.setBlock(x + 1, y + 8, z + 9, Blocks.air, 0, 3);
		world.setBlock(x + 1, y + 8, z + 8, Blocks.air, 0, 3);
		world.setBlock(x + 1, y + 8, z + 7, Blocks.air, 0, 3);
		world.setBlock(x + 1, y + 8, z + 6, Blocks.air, 0, 3);
		world.setBlock(x + 1, y + 8, z + 5, Blocks.air, 0, 3);
		world.setBlock(x + 1, y + 8, z + 4, Blocks.air, 0, 3);
		world.setBlock(x + 1, y + 8, z + 3, Blocks.air, 0, 3);
		world.setBlock(x + 1, y + 8, z + 2, Blocks.air, 0, 3);
		world.setBlock(x + 1, y + 8, z + 1, Blocks.air, 0, 3);
		world.setBlock(x + 1, y + 8, z + 0, Blocks.air, 0, 3);
		world.setBlock(x + 2, y + 8, z + 9, Blocks.air, 0, 3);
		world.setBlock(x + 2, y + 8, z + 8, Blocks.air, 0, 3);
		world.setBlock(x + 2, y + 8, z + 7, Blocks.air, 0, 3);
		world.setBlock(x + 2, y + 8, z + 6, Blocks.air, 0, 3);
		world.setBlock(x + 2, y + 8, z + 5, Blocks.air, 0, 3);
		world.setBlock(x + 2, y + 8, z + 4, Blocks.air, 0, 3);
		world.setBlock(x + 2, y + 8, z + 3, Blocks.air, 0, 3);
		world.setBlock(x + 2, y + 8, z + 2, Blocks.air, 0, 3);
		world.setBlock(x + 2, y + 8, z + 1, Blocks.air, 0, 3);
		world.setBlock(x + 2, y + 8, z + 0, Blocks.air, 0, 3);
		world.setBlock(x + 3, y + 8, z + 9, Blocks.air, 0, 3);
		world.setBlock(x + 3, y + 8, z + 8, Blocks.stone_slab, 4, 3);
		world.setBlock(x + 3, y + 8, z + 7, Blocks.air, 0, 3);
		world.setBlock(x + 3, y + 8, z + 6, Blocks.air, 0, 3);
		world.setBlock(x + 3, y + 8, z + 5, Blocks.air, 0, 3);
		world.setBlock(x + 3, y + 8, z + 4, Blocks.air, 0, 3);
		world.setBlock(x + 3, y + 8, z + 3, Blocks.air, 0, 3);
		world.setBlock(x + 3, y + 8, z + 2, Blocks.air, 0, 3);
		world.setBlock(x + 3, y + 8, z + 1, Blocks.air, 0, 3);
		world.setBlock(x + 3, y + 8, z + 0, Blocks.air, 0, 3);
		world.setBlock(x + 4, y + 8, z + 9, Blocks.air, 0, 3);
		world.setBlock(x + 4, y + 8, z + 8, Blocks.air, 0, 3);
		world.setBlock(x + 4, y + 8, z + 7, Blocks.air, 0, 3);
		world.setBlock(x + 4, y + 8, z + 6, Blocks.air, 0, 3);
		world.setBlock(x + 4, y + 8, z + 5, Blocks.air, 0, 3);
		world.setBlock(x + 4, y + 8, z + 4, Blocks.air, 0, 3);
		world.setBlock(x + 4, y + 8, z + 3, Blocks.air, 0, 3);
		world.setBlock(x + 4, y + 8, z + 2, Blocks.air, 0, 3);
		world.setBlock(x + 4, y + 8, z + 1, Blocks.air, 0, 3);
		world.setBlock(x + 4, y + 8, z + 0, Blocks.air, 0, 3);
		world.setBlock(x + 5, y + 8, z + 9, Blocks.air, 0, 3);
		world.setBlock(x + 5, y + 8, z + 8, Blocks.air, 0, 3);
		world.setBlock(x + 5, y + 8, z + 7, Blocks.air, 0, 3);
		world.setBlock(x + 5, y + 8, z + 6, Blocks.air, 0, 3);
		world.setBlock(x + 5, y + 8, z + 5, Blocks.air, 0, 3);
		world.setBlock(x + 5, y + 8, z + 4, Blocks.air, 0, 3);
		world.setBlock(x + 5, y + 8, z + 3, Blocks.air, 0, 3);
		world.setBlock(x + 5, y + 8, z + 2, Blocks.air, 0, 3);
		world.setBlock(x + 5, y + 8, z + 1, Blocks.air, 0, 3);
		world.setBlock(x + 5, y + 8, z + 0, Blocks.air, 0, 3);
		world.setBlock(x + 6, y + 8, z + 9, Blocks.air, 0, 3);
		world.setBlock(x + 6, y + 8, z + 8, Blocks.air, 0, 3);
		world.setBlock(x + 6, y + 8, z + 7, Blocks.air, 0, 3);
		world.setBlock(x + 6, y + 8, z + 6, Blocks.air, 0, 3);
		world.setBlock(x + 6, y + 8, z + 5, Blocks.air, 0, 3);
		world.setBlock(x + 6, y + 8, z + 4, Blocks.air, 0, 3);
		world.setBlock(x + 6, y + 8, z + 3, Blocks.air, 0, 3);
		world.setBlock(x + 6, y + 8, z + 2, Blocks.air, 0, 3);
		world.setBlock(x + 6, y + 8, z + 1, Blocks.air, 0, 3);
		world.setBlock(x + 6, y + 8, z + 0, Blocks.air, 0, 3);
		return generateR13Last(world, rand, x, y, z);

	}

	public boolean generateR13Last(World world, Random rand, int x, int y, int z) {
		world.setBlock(x + 4, y + 2, z + 4, Blocks.torch, 2, 3);
		world.setBlock(x + 6, y + 2, z + 4, Blocks.torch, 1, 3);
		world.setBlock(x + 5, y + 1, z + 3, Blocks.wooden_door, 2, 3);
		world.setBlock(x + 5, y + 2, z + 3, Blocks.wooden_door, 8, 3);
		world.setBlock(x + 3, y + 1, z + 2, Blocks.chest, 0, 3);
		boolean flag = generateChest(world, rand, x + 3, y + 1, z + 2);
		world.setBlock(x + 3, y + 1, z + 8, Blocks.furnace, 0, 3);
		world.setBlock(x + 2, y + 1, z + 2, Blocks.crafting_table, 0, 3);
		boolean flag1 = generateVillager(world, rand, x + 2, y + 1, z + 3);
		world.setBlock(x + 2, y + 1, z + 5, Blocks.bed, 8, 3);
		world.setBlock(x + 2, y + 1, z + 4, Blocks.bed, 0, 3);
		return flag && flag1;
	}

	public boolean generateR2(World world, Random rand, int x, int y, int z) {
		if (!canGenerateLocal(world, x, y, z, x + 9, z + 6)) {
			return false;
		}
		world.setBlock(x + 9, y + -1, z + 6, Blocks.cobblestone, 0, 3);
		world.setBlock(x + 8, y + -1, z + 6, Blocks.cobblestone, 0, 3);
		world.setBlock(x + 7, y + -1, z + 6, Blocks.cobblestone, 0, 3);
		world.setBlock(x + 6, y + -1, z + 6, Blocks.cobblestone, 0, 3);
		world.setBlock(x + 5, y + -1, z + 6, Blocks.cobblestone, 0, 3);
		world.setBlock(x + 4, y + -1, z + 6, Blocks.cobblestone, 0, 3);
		world.setBlock(x + 3, y + -1, z + 6, Blocks.cobblestone, 0, 3);
		world.setBlock(x + 2, y + -1, z + 6, Blocks.cobblestone, 0, 3);
		world.setBlock(x + 1, y + -1, z + 6, Blocks.cobblestone, 0, 3);
		world.setBlock(x + 0, y + -1, z + 6, Blocks.cobblestone, 0, 3);
		world.setBlock(x + 9, y + -1, z + 5, Blocks.cobblestone, 0, 3);
		world.setBlock(x + 8, y + -1, z + 5, Blocks.cobblestone, 0, 3);
		world.setBlock(x + 7, y + -1, z + 5, Blocks.cobblestone, 0, 3);
		world.setBlock(x + 6, y + -1, z + 5, Blocks.cobblestone, 0, 3);
		world.setBlock(x + 5, y + -1, z + 5, Blocks.cobblestone, 0, 3);
		world.setBlock(x + 4, y + -1, z + 5, Blocks.cobblestone, 0, 3);
		world.setBlock(x + 3, y + -1, z + 5, Blocks.cobblestone, 0, 3);
		world.setBlock(x + 2, y + -1, z + 5, Blocks.cobblestone, 0, 3);
		world.setBlock(x + 1, y + -1, z + 5, Blocks.cobblestone, 0, 3);
		world.setBlock(x + 0, y + -1, z + 5, Blocks.cobblestone, 0, 3);
		world.setBlock(x + 9, y + -1, z + 4, Blocks.cobblestone, 0, 3);
		world.setBlock(x + 8, y + -1, z + 4, Blocks.cobblestone, 0, 3);
		world.setBlock(x + 7, y + -1, z + 4, Blocks.cobblestone, 0, 3);
		world.setBlock(x + 6, y + -1, z + 4, Blocks.cobblestone, 0, 3);
		world.setBlock(x + 5, y + -1, z + 4, Blocks.cobblestone, 0, 3);
		world.setBlock(x + 4, y + -1, z + 4, Blocks.cobblestone, 0, 3);
		world.setBlock(x + 3, y + -1, z + 4, Blocks.cobblestone, 0, 3);
		world.setBlock(x + 2, y + -1, z + 4, Blocks.cobblestone, 0, 3);
		world.setBlock(x + 1, y + -1, z + 4, Blocks.cobblestone, 0, 3);
		world.setBlock(x + 0, y + -1, z + 4, Blocks.cobblestone, 0, 3);
		world.setBlock(x + 9, y + -1, z + 3, Blocks.cobblestone, 0, 3);
		world.setBlock(x + 8, y + -1, z + 3, Blocks.cobblestone, 0, 3);
		world.setBlock(x + 7, y + -1, z + 3, Blocks.cobblestone, 0, 3);
		world.setBlock(x + 6, y + -1, z + 3, Blocks.cobblestone, 0, 3);
		world.setBlock(x + 5, y + -1, z + 3, Blocks.cobblestone, 0, 3);
		world.setBlock(x + 4, y + -1, z + 3, Blocks.cobblestone, 0, 3);
		world.setBlock(x + 3, y + -1, z + 3, Blocks.cobblestone, 0, 3);
		world.setBlock(x + 2, y + -1, z + 3, Blocks.cobblestone, 0, 3);
		world.setBlock(x + 1, y + -1, z + 3, Blocks.cobblestone, 0, 3);
		world.setBlock(x + 0, y + -1, z + 3, Blocks.cobblestone, 0, 3);
		world.setBlock(x + 9, y + -1, z + 2, Blocks.cobblestone, 0, 3);
		world.setBlock(x + 8, y + -1, z + 2, Blocks.cobblestone, 0, 3);
		world.setBlock(x + 7, y + -1, z + 2, Blocks.cobblestone, 0, 3);
		world.setBlock(x + 6, y + -1, z + 2, Blocks.cobblestone, 0, 3);
		world.setBlock(x + 5, y + -1, z + 2, Blocks.cobblestone, 0, 3);
		world.setBlock(x + 4, y + -1, z + 2, Blocks.cobblestone, 0, 3);
		world.setBlock(x + 3, y + -1, z + 2, Blocks.cobblestone, 0, 3);
		world.setBlock(x + 2, y + -1, z + 2, Blocks.cobblestone, 0, 3);
		world.setBlock(x + 1, y + -1, z + 2, Blocks.cobblestone, 0, 3);
		world.setBlock(x + 0, y + -1, z + 2, Blocks.cobblestone, 0, 3);
		world.setBlock(x + 9, y + -1, z + 1, Blocks.cobblestone, 0, 3);
		world.setBlock(x + 8, y + -1, z + 1, Blocks.cobblestone, 0, 3);
		world.setBlock(x + 7, y + -1, z + 1, Blocks.cobblestone, 0, 3);
		world.setBlock(x + 6, y + -1, z + 1, Blocks.cobblestone, 0, 3);
		world.setBlock(x + 5, y + -1, z + 1, Blocks.cobblestone, 0, 3);
		world.setBlock(x + 4, y + -1, z + 1, Blocks.cobblestone, 0, 3);
		world.setBlock(x + 3, y + -1, z + 1, Blocks.cobblestone, 0, 3);
		world.setBlock(x + 2, y + -1, z + 1, Blocks.cobblestone, 0, 3);
		world.setBlock(x + 1, y + -1, z + 1, Blocks.cobblestone, 0, 3);
		world.setBlock(x + 0, y + -1, z + 1, Blocks.cobblestone, 0, 3);
		world.setBlock(x + 9, y + -1, z + 0, Blocks.cobblestone, 0, 3);
		world.setBlock(x + 8, y + -1, z + 0, Blocks.cobblestone, 0, 3);
		world.setBlock(x + 7, y + -1, z + 0, Blocks.cobblestone, 0, 3);
		world.setBlock(x + 6, y + -1, z + 0, Blocks.cobblestone, 0, 3);
		world.setBlock(x + 5, y + -1, z + 0, Blocks.cobblestone, 0, 3);
		world.setBlock(x + 4, y + -1, z + 0, Blocks.cobblestone, 0, 3);
		world.setBlock(x + 3, y + -1, z + 0, Blocks.cobblestone, 0, 3);
		world.setBlock(x + 2, y + -1, z + 0, Blocks.cobblestone, 0, 3);
		world.setBlock(x + 1, y + -1, z + 0, Blocks.cobblestone, 0, 3);
		world.setBlock(x + 0, y + -1, z + 0, Blocks.cobblestone, 0, 3);
		world.setBlock(x + 9, y + 0, z + 6, Blocks.air, 0, 3);
		world.setBlock(x + 8, y + 0, z + 6, Blocks.air, 0, 3);
		world.setBlock(x + 7, y + 0, z + 6, Blocks.air, 0, 3);
		world.setBlock(x + 6, y + 0, z + 6, Blocks.air, 0, 3);
		world.setBlock(x + 5, y + 0, z + 6, Blocks.air, 0, 3);
		world.setBlock(x + 4, y + 0, z + 6, Blocks.air, 0, 3);
		world.setBlock(x + 3, y + 0, z + 6, Blocks.air, 0, 3);
		world.setBlock(x + 2, y + 0, z + 6, Blocks.air, 0, 3);
		world.setBlock(x + 1, y + 0, z + 6, Blocks.air, 0, 3);
		world.setBlock(x + 0, y + 0, z + 6, Blocks.air, 0, 3);
		world.setBlock(x + 9, y + 0, z + 5, Blocks.air, 0, 3);
		world.setBlock(x + 8, y + 0, z + 5, PeatizedBlocks.peat, 0, 3);
		world.setBlock(x + 7, y + 0, z + 5, PeatizedBlocks.peat, 0, 3);
		world.setBlock(x + 6, y + 0, z + 5, PeatizedBlocks.peat, 0, 3);
		world.setBlock(x + 5, y + 0, z + 5, PeatizedBlocks.peat, 0, 3);
		world.setBlock(x + 4, y + 0, z + 5, PeatizedBlocks.peat, 0, 3);
		world.setBlock(x + 3, y + 0, z + 5, PeatizedBlocks.peat, 0, 3);
		world.setBlock(x + 2, y + 0, z + 5, PeatizedBlocks.peat, 0, 3);
		world.setBlock(x + 1, y + 0, z + 5, Blocks.log, 0, 3);
		world.setBlock(x + 0, y + 0, z + 5, Blocks.air, 0, 3);
		world.setBlock(x + 9, y + 0, z + 4, Blocks.brick_block, 0, 3);
		world.setBlock(x + 8, y + 0, z + 4, Blocks.brick_block, 0, 3);
		world.setBlock(x + 7, y + 0, z + 4, Blocks.brick_block, 0, 3);
		world.setBlock(x + 6, y + 0, z + 4, PeatizedBlocks.peat, 0, 3);
		world.setBlock(x + 5, y + 0, z + 4, PeatizedBlocks.peat, 0, 3);
		world.setBlock(x + 4, y + 0, z + 4, PeatizedBlocks.peat, 0, 3);
		world.setBlock(x + 3, y + 0, z + 4, PeatizedBlocks.peat, 0, 3);
		world.setBlock(x + 2, y + 0, z + 4, PeatizedBlocks.peat, 0, 3);
		world.setBlock(x + 1, y + 0, z + 4, PeatizedBlocks.peat, 0, 3);
		world.setBlock(x + 0, y + 0, z + 4, Blocks.air, 0, 3);
		world.setBlock(x + 9, y + 0, z + 3, Blocks.brick_block, 0, 3);
		world.setBlock(x + 8, y + 0, z + 3, Blocks.brick_block, 0, 3);
		world.setBlock(x + 7, y + 0, z + 3, Blocks.brick_block, 0, 3);
		world.setBlock(x + 6, y + 0, z + 3, PeatizedBlocks.peat, 0, 3);
		world.setBlock(x + 5, y + 0, z + 3, PeatizedBlocks.peat, 0, 3);
		world.setBlock(x + 4, y + 0, z + 3, PeatizedBlocks.peat, 0, 3);
		world.setBlock(x + 3, y + 0, z + 3, PeatizedBlocks.peat, 0, 3);
		world.setBlock(x + 2, y + 0, z + 3, PeatizedBlocks.peat, 0, 3);
		world.setBlock(x + 1, y + 0, z + 3, PeatizedBlocks.peat, 0, 3);
		world.setBlock(x + 0, y + 0, z + 3, Blocks.air, 0, 3);
		world.setBlock(x + 9, y + 0, z + 2, Blocks.brick_block, 0, 3);
		world.setBlock(x + 8, y + 0, z + 2, Blocks.brick_block, 0, 3);
		world.setBlock(x + 7, y + 0, z + 2, Blocks.brick_block, 0, 3);
		world.setBlock(x + 6, y + 0, z + 2, PeatizedBlocks.peat, 0, 3);
		world.setBlock(x + 5, y + 0, z + 2, PeatizedBlocks.peat, 0, 3);
		world.setBlock(x + 4, y + 0, z + 2, PeatizedBlocks.peat, 0, 3);
		world.setBlock(x + 3, y + 0, z + 2, PeatizedBlocks.peat, 0, 3);
		world.setBlock(x + 2, y + 0, z + 2, PeatizedBlocks.peat, 0, 3);
		world.setBlock(x + 1, y + 0, z + 2, PeatizedBlocks.peat, 0, 3);
		world.setBlock(x + 0, y + 0, z + 2, Blocks.air, 0, 3);
		world.setBlock(x + 9, y + 0, z + 1, Blocks.air, 0, 3);
		world.setBlock(x + 8, y + 0, z + 1, PeatizedBlocks.peat, 0, 3);
		world.setBlock(x + 7, y + 0, z + 1, PeatizedBlocks.peat, 0, 3);
		world.setBlock(x + 6, y + 0, z + 1, PeatizedBlocks.peat, 0, 3);
		world.setBlock(x + 5, y + 0, z + 1, PeatizedBlocks.peat, 0, 3);
		world.setBlock(x + 4, y + 0, z + 1, PeatizedBlocks.peat, 0, 3);
		world.setBlock(x + 3, y + 0, z + 1, PeatizedBlocks.peat, 0, 3);
		world.setBlock(x + 2, y + 0, z + 1, PeatizedBlocks.peat, 0, 3);
		world.setBlock(x + 1, y + 0, z + 1, Blocks.log, 0, 3);
		world.setBlock(x + 0, y + 0, z + 1, Blocks.air, 0, 3);
		world.setBlock(x + 9, y + 0, z + 0, Blocks.air, 0, 3);
		world.setBlock(x + 8, y + 0, z + 0, Blocks.air, 0, 3);
		world.setBlock(x + 7, y + 0, z + 0, Blocks.air, 0, 3);
		world.setBlock(x + 6, y + 0, z + 0, Blocks.air, 0, 3);
		world.setBlock(x + 5, y + 0, z + 0, Blocks.air, 0, 3);
		world.setBlock(x + 4, y + 0, z + 0, Blocks.air, 0, 3);
		world.setBlock(x + 3, y + 0, z + 0, Blocks.air, 0, 3);
		world.setBlock(x + 2, y + 0, z + 0, Blocks.air, 0, 3);
		world.setBlock(x + 1, y + 0, z + 0, Blocks.air, 0, 3);
		world.setBlock(x + 0, y + 0, z + 0, Blocks.air, 0, 3);
		world.setBlock(x + 9, y + 1, z + 6, Blocks.air, 0, 3);
		world.setBlock(x + 8, y + 1, z + 6, Blocks.air, 0, 3);
		world.setBlock(x + 7, y + 1, z + 6, Blocks.air, 0, 3);
		world.setBlock(x + 6, y + 1, z + 6, Blocks.air, 0, 3);
		world.setBlock(x + 5, y + 1, z + 6, Blocks.air, 0, 3);
		world.setBlock(x + 4, y + 1, z + 6, Blocks.air, 0, 3);
		world.setBlock(x + 3, y + 1, z + 6, Blocks.air, 0, 3);
		world.setBlock(x + 2, y + 1, z + 6, Blocks.air, 0, 3);
		world.setBlock(x + 1, y + 1, z + 6, Blocks.air, 0, 3);
		world.setBlock(x + 0, y + 1, z + 6, Blocks.air, 0, 3);
		world.setBlock(x + 9, y + 1, z + 5, Blocks.air, 0, 3);
		world.setBlock(x + 8, y + 1, z + 5, Blocks.log, 0, 3);
		world.setBlock(x + 7, y + 1, z + 5, Blocks.planks, 0, 3);
		world.setBlock(x + 6, y + 1, z + 5, Blocks.planks, 0, 3);
		world.setBlock(x + 5, y + 1, z + 5, Blocks.planks, 0, 3);
		world.setBlock(x + 4, y + 1, z + 5, Blocks.planks, 0, 3);
		world.setBlock(x + 3, y + 1, z + 5, Blocks.planks, 0, 3);
		world.setBlock(x + 2, y + 1, z + 5, Blocks.planks, 0, 3);
		world.setBlock(x + 1, y + 1, z + 5, Blocks.log, 0, 3);
		world.setBlock(x + 0, y + 1, z + 5, Blocks.air, 0, 3);
		world.setBlock(x + 9, y + 1, z + 4, Blocks.brick_stairs, 1, 3);
		world.setBlock(x + 8, y + 1, z + 4, Blocks.brick_block, 0, 3);
		world.setBlock(x + 7, y + 1, z + 4, Blocks.brick_stairs, 0, 3);
		world.setBlock(x + 6, y + 1, z + 4, Blocks.air, 0, 3);
		world.setBlock(x + 3, y + 1, z + 4, Blocks.air, 0, 3);
		world.setBlock(x + 1, y + 1, z + 4, Blocks.planks, 0, 3);
		world.setBlock(x + 0, y + 1, z + 4, Blocks.air, 0, 3);
		world.setBlock(x + 9, y + 1, z + 3, Blocks.brick_block, 0, 3);
		world.setBlock(x + 7, y + 1, z + 3, Blocks.air, 0, 3);
		world.setBlock(x + 6, y + 1, z + 3, Blocks.air, 0, 3);
		world.setBlock(x + 5, y + 1, z + 3, Blocks.air, 0, 3);
		world.setBlock(x + 4, y + 1, z + 3, Blocks.air, 0, 3);
		world.setBlock(x + 3, y + 1, z + 3, Blocks.air, 0, 3);
		world.setBlock(x + 1, y + 1, z + 3, Blocks.planks, 0, 3);
		world.setBlock(x + 0, y + 1, z + 3, Blocks.air, 0, 3);
		world.setBlock(x + 9, y + 1, z + 2, Blocks.brick_stairs, 1, 3);
		world.setBlock(x + 8, y + 1, z + 2, Blocks.brick_block, 0, 3);
		world.setBlock(x + 7, y + 1, z + 2, Blocks.brick_stairs, 0, 3);
		world.setBlock(x + 6, y + 1, z + 2, Blocks.air, 0, 3);
